Workbook
Name AdhesiveList: '[1]Raw Material DB'!$Q$2:$Q$5
Name amount: #REF!
Name BagTypeList: '[1]Raw Material DB'!$X$2:$X$26
Name Barier: #REF!
Name Clear: #REF!
Name Config_302FG: #REF!
Name Config_302FGW: #REF!
Name Config_306: #REF!
Name Config_308: #REF!
Name Config_312FG: #REF!
Name Config_312W: #REF!
Name Config_NKR: #REF!
Name Config_PL2021: "'Film Pricing- New'!$AF$10:$AF$20"
Name Config_PL2022: "'Film Pricing- New'!$AG$10:$AG$20"
Name Config_PL2023: "'Film Pricing- New'!$AH$10:$AH$20"
Name Family: #REF!
Name Film_type: '[3]List of names'!$W$15:$W$16
Name FilmList: #REF!
Name GF048.1: #REF!
Name Grouped: #REF!
Name HardenerList: '[1]Raw Material DB'!$U$2:$U$4
Name JOB: OFFSET('[4]GEF063 WP Sales'!B6,0,0,COUNTA('[4]GEF063 WP Sales'!$AS$11:$AS$200),COUNTA('[4]GEF063 WP Sales'!$AS$11:$AT$11))
Name Jobs: '[4]GEF063 WP Sales'!$AS$10:$AS$210+'[4]GEF063 WP Sales'!$AU$10-2
Name Jobss: '[4]GEF063 WP Sales'!XFC2:XFC2+VALUE('[4]GEF063 WP Sales'!$AU$10)
Name Laminate: '[3]List of names'!$P$15:$P$18
Name Laminate_Thickness: #REF!
Name Laminate_type: '[5]List of names'!$P$14:$X$14
Name Laminate106: [3]!Table2[Laminate106]
Name Laminate604: [3]!Table4[Laminate608]
Name Laminate607: [3]!Table6[Laminate607]
Name Laminate607\: [3]!Table6[Laminate607]
Name Laminate608W: [3]!Table3[Laminate608 W]
Name LaminateList: '[1]Raw Material DB'!$M$20:$M$82
Name MATERIAL: '[6]Raw materials prices'!$L$51:$L$61
Name Materials: '[7]list for drop down menu'!$A$1:$A$20
Name Metalize: #REF!
Name NKR: '[1]List of names'!#REF!
Name Paper: #REF!
Name pirce: #REF!
Name PO: #REF!
Name price: #REF!
Name ShippingRoutes: HELPER!$AF$2:$AF$4
Name ThicknessList: #REF!
Name USD: '[3]Raw material summary'!$F$3
Name width: #REF!
Name Film_type: '[2]List of names'!$Y$15:$Y$16
Name Laminate: '[2]List of names'!$P$15:$P$22
Name Laminate_type: '[2]List of names'!$P$14:$X$14
Name Laminate604: [2]!Table4[Laminate618]
Name Laminate608W: [2]!Table3[Laminate608W]
Name USD: '[2]Raw material summary'!$F$3

Sheet Sheet1
A3: Film | B3: Grade | C3: Sum of Price Calculated(€) Thickness & QTY related
A4: TIPA 302FG | B4: S723 | C4: 0.2424
B5: S724 | C5: 0.02352
A6: TIPA 302FG W | B6: S723 | C6: 0.2424
B7: S724 | C7: 0.09408
A8: TIPA 306M | B8: S723 | C8: 0.2424
B9: S724 | C9: 0.0588
A10: TIPA 306W | B10: S723 | C10: 0.2424
B11: S724 | C11: 0.1176
A12: TIPA 312 MFG | B12: S723 | C12: 0.2424
B13: S724 | C13: 0.06762
A14: TIPA 312MFGW | B14: S723 | C14: 0.2424
B15: S724 | C15: 0.06762
A16: Grand Total | C16: 1.88364
A20: Film | B20: Price (€/kg) | C20: Price ($/kg)
A21: PL202.1 | B21: 8.995784 | C21: 10.435109
A22: PL202.2 | B22: 6.73178 | C22: 7.8088648
A23: PL202.3 | B23: 5.74578 | C23: 6.6651048
A24: TIPA 302FG | B24: 3.599712 | C24: 4.1756659
A25: TIPA 302FG W | B25: 3.916872 | C25: 4.5435715
A26: TIPA 306M | B26: 3.520798 | C26: 4.0841257
A27: TIPA 306W | B27: 3.805774 | C27: 4.4146978
A28: TIPA 312 MFG | B28: 2.899978 | C28: 3.3639745
A29: TIPA 312MFGW | B29: 3.178978 | C29: 3.6876145
A32: FILM | B32: Material | C32: % from Total
A33: TIPA 302FG | B33: S723 | C33: =C4/$B$24
B34: S724 | C34: =C5/$B$24
A35: TIPA 302FG W | B35: S723 | C35: =C6/$B$25
B36: S724 | C36: =C7/$B$25
A37: TIPA 306M | B37: S723 | C37: =C8/$B$26
B38: S724 | C38: =C9/$B$26
A39: TIPA 306W | B39: S723 | C39: =C10/$B$27
B40: S724 | C40: =C11/$B$27
A41: TIPA 312 MFG | B41: S723 | C41: =C12/$B$28
B42: S724 | C42: =C13/$B$28
A43: TIPA 312MFGW | B43: S723 | C43: =C14/$B$29
B44: S724 | C44: =C15/$B$29

Sheet Step by Step
B2: 📋 FILM PRICING LIST - STEP BY STEP GUIDE
B3: How to use the Film Pricing calculator
B5: 🔄 PRICING WORKFLOW
B7: STEP 1 | C7: → | D7: STEP 2 | E7: → | F7: STEP 3 | G7: → | H7: STEP 4 | I7: → | J7: STEP 5
B8: 📝 INPUT | D8: ⚙️ SPECS | F8: 💰 COSTS | H8: 📦 SHIP | J8: 💵 PRICE
B11: 📝 DETAILED STEPS
B13: Step | C13: Action | D13: Column | E13: Example | F13: Notes
B14: 1️⃣ | C14: Select Film Type | D14: A | E14: TIPA 302FG | F14: Dropdown list
B15: 2️⃣ | C15: Enter Width | D15: B | E15: 406 mm | F15: Width in mm
B16: 3️⃣ | C16: Enter Thickness | D16: C | E16: 20 µ | F16: Dropdown list
B17: 4️⃣ | C17: Enter Weight | D17: E | E17: 500 Kg | F17: Order qty (Kg)
B18: 5️⃣ | C18: Weight Override | D18: F | E18: 500 Kg | F18: Optional
B19: 6️⃣ | C19: Shipping Dest. | D19: S | E19: EU/USA | F19: Dropdown list
B20: 7️⃣ | C20: Review Price | D20: W | E20: Auto | F20: Final price/Kg
B21: 8️⃣ | C21: Compare Margins | D21: X+ | E21: 25%, 30% | F21: Multiple options
B24: ⚡ AUTO-CALCULATIONS
B26: Calculation | C26: Formula Logic
B27: Length (Mr) | C27: Weight ÷ (Width × Thickness × Density)
B28: Production Cost | C28: Hourly Rate × Production Time
B29: Total Cost | C29: RM + Production + Depreciation + Waste + Ship
B30: Sell Price | C30: Total Cost × (1 + Margin %)
B33: 💡 QUICK TIPS
B35: ✓ Use dropdowns to avoid typos
B36: ✓ Higher weight = lower cost/Kg (economies of scale)
B37: ✓ Compare margin columns for pricing options
B38: ✓ Density auto-fills based on Film Type

Sheet Film -Summary Pricing
A1: Tipa 303B&W | F1: All changes to paramters should be in Film Summary
A2: Tipa302WFG | S2: 0.25
A3: TIPA 303 W | I3: עלויות ייצור | K3: סה"כ | L3: 0.15 | M3: ='[2]Film -Summary'!M3 | S3: 0.225 | T3: =S3/100/(1+S3)
A4: Film | B4: Width (mm) | C4: Length (Mr) | D4: Thickenes (µ) | E4: צפיפות | F4: Total KG in one Meter | G4: Total Kg Produced | H4: Hourly rate | I4: 1Kg production cost | J4: RM cost in 1 Kg | K4: To tal RM and Production | L4: Total Cost and depreciation | M4: Dep | N4: Other costs | O4: Basc Cost | P4: SET UP | Q4: Printing | R4: Shipping & Customs | S4: Total Cost | T4: Selling price | W4: Producer
A5: Tipa302FG | B5: 1800 | C5: 1 | D5: 20 | E5: 1.25 | F5: =C5*E5*(D5/1000)*(B5/1000) | G5: 450 | H5: 510 | I5: =H5/G5+0.2 | J5: =VLOOKUP(A5,'[2]Raw material summary'!A:B,2,0) | K5: =J5+I5 | L5: =K5*(1+$L$3) | M5: 0.15 | N5: =L5*$M$3 | O5: =L5+N5 | P5: =1550*2/60000 | S5: =SUM(O5:R5) | T5: =S5/(1-($S$3)) | U5: =2000*F5 | V5: =U5*T5
A6: Tipa302FG | B6: 1800 | C6: 1 | D6: 25 | E6: 1.25 | F6: =C6*E6*(D6/1000)*(B6/1000) | G6: 500 | H6: =H5 | I6: =H6/G6+0.2 | J6: =VLOOKUP(A6,'[2]Raw material summary'!A:B,2,0) | K6: =J6+I6 | L6: =K6*(1+$L$3) | M6: 0.15 | N6: =L6*$M$3 | O6: =L6+N6 | P6: =1550*2/60000 | S6: =SUM(O6:R6) | T6: =S6/(1-($S$3))
A7: Tipa302FG | B7: 1800 | C7: 1 | D7: 30 | E7: 1.25 | F7: =C7*E7*(D7/1000)*(B7/1000) | G7: 500 | H7: =H6 | I7: =H7/G7+0.2 | J7: =VLOOKUP(A7,'[2]Raw material summary'!A:B,2,0) | K7: =J7+I7 | L7: =K7*(1+$L$3) | M7: 0.15 | N7: =L7*$M$3 | O7: =L7+N7 | P7: =1550*2/60000 | S7: =SUM(O7:R7) | T7: =S7/(1-($S$3)) | U7: =1/F7*25
A8: Tipa302FG | B8: 1800 | C8: 1 | D8: 35 | E8: 1.25 | F8: =C8*E8*(D8/1000)*(B8/1000) | G8: 500 | H8: =H7 | I8: =H8/G8+0.2 | J8: =VLOOKUP(A8,'[2]Raw material summary'!A:B,2,0) | K8: =J8+I8 | L8: =K8*(1+$L$3) | M8: 0.15 | N8: =L8*$M$3 | O8: =L8+N8 | P8: =1550*2/60000 | S8: =SUM(O8:R8) | T8: =S8/(1-($S$3))
A9: Tipa302FG | B9: 1800 | C9: 1 | D9: 40 | E9: 1.25 | F9: =C9*E9*(D9/1000)*(B9/1000) | G9: 500 | H9: =H8 | I9: =H9/G9+0.2 | J9: =VLOOKUP(A9,'[2]Raw material summary'!A:B,2,0) | K9: =J9+I9 | L9: =K9*(1+$L$3) | M9: 0.15 | N9: =L9*$M$3 | O9: =L9+N9 | P9: =1550*2/60000 | S9: =SUM(O9:R9) | T9: =S9/(1-($S$3))
A10: Tipa302FG | B10: 1800 | C10: 1 | D10: 50 | E10: 1.25 | F10: =C10*E10*(D10/1000)*(B10/1000) | G10: 500 | H10: =H9 | I10: =H10/G10+0.2 | J10: =VLOOKUP(A10,'[2]Raw material summary'!A:B,2,0) | K10: =J10+I10 | L10: =K10*(1+$L$3) | M10: 0.15 | N10: =L10*$M$3 | O10: =L10+N10 | P10: =1550*2/60000 | S10: =SUM(O10:R10) | T10: =S10/(1-($S$3))
A11: Tipa302FG | B11: 1800 | C11: 1 | D11: 60 | E11: 1.25 | F11: =C11*E11*(D11/1000)*(B11/1000) | G11: 500 | H11: =H10 | I11: =H11/G11+0.2 | J11: =VLOOKUP(A11,'[2]Raw material summary'!A:B,2,0) | K11: =J11+I11 | L11: =K11*(1+$L$3) | M11: 0.15 | N11: =L11*$M$3 | O11: =L11+N11 | P11: =1550*2/60000 | S11: =SUM(O11:R11) | T11: =S11/(1-($S$3)) | AB11: =19839/5
A12: Tipa302FG | B12: 1800 | C12: 1 | D12: 70 | E12: 1.25 | F12: =C12*E12*(D12/1000)*(B12/1000) | G12: 500 | H12: =H11 | I12: =H12/G12+0.2 | J12: =VLOOKUP(A12,'[2]Raw material summary'!A:B,2,0) | K12: =J12+I12 | L12: =K12*(1+$L$3) | M12: 0.15 | N12: =L12*$M$3 | O12: =L12+N12 | P12: =1550*2/60000 | S12: =SUM(O12:R12) | T12: =S12/(1-($S$3))
A13: Tipa302FG | B13: 1800 | C13: 1 | D13: 80 | E13: 1.25 | F13: =C13*E13*(D13/1000)*(B13/1000) | G13: 500 | H13: =H12 | I13: =H13/G13+0.2 | J13: =VLOOKUP(A13,'[2]Raw material summary'!A:B,2,0) | K13: =J13+I13 | L13: =K13*(1+$L$3) | M13: 0.15 | N13: =L13*$M$3 | O13: =L13+N13 | P13: =1550*2/60000 | R13: 0.2 | S13: =SUM(O13:R13) | T13: =S13/(1-($S$3))
A15: =A25 | B15: =B25 | C15: 1 | D15: =C25 | E15: 1.25 | F15: =C15*E15*(D15/1000)*(B15/1000) | G15: =VLOOKUP(D15,$D$5:$G$13,4,0) | H15: =$H$5 | I15: =IF(W15="Verbano",0.8,IF(W15="Polifilm","X",H15/G15+0.2)) | J15: =VLOOKUP(A15,'[2]Raw material summary'!A:B,2,0) | K15: =J15+I15 | L15: =K15*(1+M15) | M15: =IF(F25>=$D$36,$E$37,IF(F25>=$C$36,$D$37,IF(F25>=$B$36,$C$37,$B$37)))+IF(OR(D15=25,D15=20),$B$41,IF(D15=30,$B$40,0)) | N15: =IF(OR(A15=$A$1,A15=$A$2,A15=$A$3),1500/F25,0)+0.3 | O15: =L15+N15 | P15: =IF(W15="Verbano",30/60*500*K15/20000,(1500+3000)/30000) | Q15: 4 | R15: =9*0.15+3 | S15: =SUM(O15:R15) | T15: =S15/(1-($S$3)) | U15: =1000*F15 | W15: Gefo | Y15: =T15*F25 | AB15: Verbano
A16: =A26 | B16: =B26 | C16: 1 | D16: =C26 | E16: 1.25 | F16: =C16*E16*(D16/1000)*(B16/1000) | G16: =VLOOKUP(D16,$D$5:$G$13,4,0) | H16: =$H$5 | I16: =IF(W16="Verbano",0.8,IF(W16="Polifilm","X",H16/G16+0.2)) | J16: =VLOOKUP(A16,'[2]Raw material summary'!A:B,2,0) | K16: =J16+I16 | L16: =K16*(1+M16) | M16: =IF(F26>=$D$36,$E$37,IF(F26>=$C$36,$D$37,IF(F26>=$B$36,$C$37,$B$37)))+IF(OR(D16=25,D16=20),$B$41,IF(D16=30,$B$40,0)) | N16: =IF(OR(A16=$A$1,A16=$A$2,A16=$A$3),1500/F26,0)+0.3 | O16: =L16+N16 | P16: =IF(W16="Verbano",30/60*500*K16/20000,(1500+3000)/30000) | S16: =SUM(O16:R16) | T16: =S16/(1-($S$3)) | W16: Gefo | Y16: =T16*F26 | AB16: Polifilm
A17: =A27 | B17: =B27 | C17: 1 | D17: =C27 | E17: 1.25 | F17: =C17*E17*(D17/1000)*(B17/1000) | G17: =VLOOKUP(D17,$D$5:$G$13,4,0) | H17: =$H$5 | I17: =IF(W17="Verbano",0.8,IF(W17="Polifilm","X",H17/G17+0.2)) | J17: =VLOOKUP(A17,'[2]Raw material summary'!A:B,2,0) | K17: =J17+I17 | L17: =K17*(1+M17) | M17: =IF(F27>=$D$36,$E$37,IF(F27>=$C$36,$D$37,IF(F27>=$B$36,$C$37,$B$37)))+IF(OR(D17=25,D17=20),$B$41,IF(D17=30,$B$40,0)) | N17: =IF(OR(A17=$A$1,A17=$A$2,A17=$A$3),1500/F27,0)+0.3 | O17: =L17+N17 | P17: =IF(W17="Verbano",30/60*500*K17/20000,(1500+3000)/30000) | S17: =SUM(O17:R17) | T17: =S17/(1-($S$3)) | W17: Gefo | Y17: =T17*F27 | AB17: Gefo
A18: =A28 | B18: =B28 | C18: 1 | D18: =C28 | E18: 1.25 | F18: =C18*E18*(D18/1000)*(B18/1000) | G18: =VLOOKUP(D18,$D$5:$G$13,4,0) | H18: =$H$5 | I18: =IF(W18="Verbano",0.8,IF(W18="Polifilm","X",H18/G18+0.2)) | J18: =VLOOKUP(A18,'[2]Raw material summary'!A:B,2,0) | K18: =J18+I18 | L18: =K18*(1+M18) | M18: =IF(F28>=$D$36,$E$37,IF(F28>=$C$36,$D$37,IF(F28>=$B$36,$C$37,$B$37)))+IF(OR(D18=25,D18=20),$B$41,IF(D18=30,$B$40,0)) | N18: =IF(OR(A18=$A$1,A18=$A$2,A18=$A$3),1500/F28,0)+0.3 | O18: =L18+N18 | P18: =IF(W18="Verbano",30/60*500*K18/20000,(1500+3000)/30000) | S18: =SUM(O18:R18) | T18: =S18/(1-($S$3)) | W18: Gefo
A19: =A29 | B19: =B29 | C19: 1 | D19: =C29 | E19: 1.25 | F19: =C19*E19*(D19/1000)*(B19/1000) | G19: =VLOOKUP(D19,$D$5:$G$13,4,0) | H19: =$H$5 | I19: =IF(W19="Verbano",0.8,IF(W19="Polifilm","X",H19/G19+0.2)) | J19: =VLOOKUP(A19,'[2]Raw material summary'!A:B,2,0) | K19: =J19+I19 | L19: =K19*(1+M19) | M19: =IF(F29>=$D$36,$E$37,IF(F29>=$C$36,$D$37,IF(F29>=$B$36,$C$37,$B$37)))+IF(OR(D19=25,D19=20),$B$41,IF(D19=30,$B$40,0))+1400/B29-1 | N19: =IF(OR(A19=$A$1,A19=$A$2,A19=$A$3),1500/F29,0)+0.3 | O19: =L19+N19 | P19: =IF(W19="Verbano",30/60*500*K19/20000,(1500+3000)/30000) | S19: =SUM(O19:R19) | T19: =S19/(1-($S$3)) | U19: 0.18 | W19: Gefo
A20: =A30 | B20: =B30 | C20: 1 | D20: =C30 | E20: 1.25 | F20: =C20*E20*(D20/1000)*(B20/1000) | G20: =VLOOKUP(D20,$D$5:$G$13,4,0) | H20: =$H$5 | I20: =IF(W20="Verbano",0.8,IF(W20="Polifilm","X",H20/G20+0.2)) | J20: =VLOOKUP(A20,'[2]Raw material summary'!A:B,2,0) | K20: =J20+I20 | L20: =K20*(1+M20) | M20: =IF(F30>=$D$36,$E$37,IF(F30>=$C$36,$D$37,IF(F30>=$B$36,$C$37,$B$37)))+IF(OR(D20=25,D20=20),$B$41,IF(D20=30,$B$40,0))+1400/B30-1 | N20: =IF(OR(A20=$A$1,A20=$A$2,A20=$A$3),1500/F30,0)+0.3 | O20: =L20+N20 | P20: =IF(W20="Verbano",30/60*500*K20/20000,(1500+3000)/30000) | S20: =SUM(O20:R20) | T20: =S20/(1-($S$3)) | W20: Gefo
H22: KG | I22: =+I25*1.08 | L22: ML
H23: Eur | J23: USD | L23: Eur | N23: USD | P23: Impression Prices
A24: Type of film | B24: Width | C24: Thickness | D24: Printed? | E24: Slitting? | F24: Weight | G24: Length | H24: Cost | I24: Price | J24: Cost | K24: Price | L24: Cost | M24: Price | N24: Cost | O24: Price | P24: Repeat | Q24: Impression in ML | R24: Number of Impression | S24: Ml | T24: Cost per Imp | U24: Price per Imp
A25: Tipa302FG | B25: 406 | C25: 35 | D25: Yes | E25: No | F25: =G25*F15 | G25: 1800000 | H25: =S15 | I25: =T15 | J25: =H25*USD | K25: =I25*USD | L25: =H25*$F15 | M25: =I25*$F15 | N25: =L25*USD | O25: =M25*USD | P25: 60 | Q25: =1000/P25 | R25: 30000000 | S25: =R25/Q25 | T25: =L25/Q25 | U25: =M25/Q25 | W25: =F25*K25
A26: Tipa302FG | B26: 434 | C26: 35 | D26: Yes | E26: No | F26: =G26*F16 | G26: =G25/2 | H26: =S16 | I26: =T16 | J26: =H26*USD | K26: =I26*USD | L26: =H26*$F16 | M26: =I26*$F16 | N26: =L26*USD | O26: =M26*USD | P26: 60 | Q26: =1000/P26 | R26: =30000000/2 | S26: =R26/Q26 | T26: =L26/Q26 | U26: =M26/Q26
A27: Tipa312W | B27: 1270 | C27: 35 | D27: No | E27: No | F27: 3000 | G27: =F27/F17 | H27: =S17 | I27: =T17 | J27: =H27*USD | K27: =I27*USD | L27: =H27*$F17 | M27: =I27*$F17 | N27: =L27*USD | O27: =M27*USD | P27: 300 | Q27: =1000/P27 | R27: 2000000 | S27: =R27/Q27 | T27: =L27/Q27 | U27: =M27/Q27
A28: Tipa312W | B28: 750 | C28: 35 | D28: No | E28: No | F28: 7000 | G28: =F28/F18 | H28: =S18 | I28: =T18 | J28: =H28*USD | K28: =I28*USD | L28: =H28*$F18 | M28: =I28*$F18 | N28: =L28*USD | O28: =M28*USD
A29: Tipa312W | B29: 1020 | C29: 35 | D29: No | E29: No | F29: 7000 | G29: =F29/F19 | H29: =S19 | I29: =T19 | J29: =H29*USD | K29: =I29*USD | L29: =H29*$F19 | M29: =I29*$F19 | N29: =L29*USD | O29: =M29*USD
A30: Tipa312W | B30: 1270 | C30: 35 | D30: No | E30: No | F30: 7000 | G30: =F30/F20 | H30: =S20 | I30: =T20 | J30: =H30*USD | K30: =I30*USD | L30: =H30*$F20 | M30: =I30*$F20 | N30: =L30*USD | O30: =M30*USD
B32: =B25*21 | C32: =760/C25 | G32: =G25/C32
A33: Paramters | C33: =760/C26 | G33: =G26/C33
A36: Weight | B36: 1000 | C36: 2000 | D36: 7000
A37: Dep | B37: 0.25 | C37: 0.2 | D37: 0.15 | E37: 0.125
A39: Dep if below 30 Micron
A40: 30 | B40: 0.05
A41: 20,25 | B41: 0.075
A43: Yes
A44: No

Sheet BOM
A1: Film | B1: Ext | C1: Material | D1: Grade | E1: Serial Number | F1: Resin | G1: Thickness (µ) | H1: QTY | I1: Price (€/kg) | J1: Price Calculated(€) Thickness & QTY related | L1: Film | M1: Grade | N1: Serial Number | O1: Price Calculated(€) Thickness & QTY related | Q1: Film | R1: Price (€/kg) | S1: Price ($/kg)
A2: TIPA 302FG | B2: Ext. A (Out - Chillroll) | C2: PBSA | D2: =IF(C2="","",IFERROR(_xlfn.XLOOKUP(C2,HELPER!$A$2:$A$76,HELPER!$B$2:$B$76,""),D2)) | E2: =IFERROR(_xlfn.XLOOKUP(D2,HELPER!$B:$B,HELPER!$C:$C,""),"") | F2: =IFERROR(_xlfn.XLOOKUP(D2,HELPER!$B:$B,HELPER!$D:$D,""),"") | G2: 8 | H2: 0.826 | I2: =IF(AND(H2<>"",IFERROR(_xlfn.XLOOKUP(D2,HELPER!$B:$B,HELPER!$E:$E,""),"")=""),"Missing price",IFERROR(_xlfn.XLOOKUP(D2,HELPER!$B:$B,HELPER!$E:$E,"")," ")) | J2: =IFERROR(H2*(IF(G2=8,I2*HELPER!$G$2,BOM!I2*HELPER!$G$3))," ") | L2: {=IFERROR(_xlfn.LET(_xlpm.pairs,_xlfn._xlws.FILTER($A$2:$D$391,($A$2:$A$391<>"")*(TRIM($D$2:$D$391)<>"")),_xlpm.uniquePairs,_xlfn.UNIQUE(_xlfn.HSTACK(INDEX(_xlpm.pairs,,1),INDEX(_xlpm.pairs,,4))),_xlpm.sortedPairs,_xlfn._xlws.SORT(_xlpm.uniquePairs,1,1),IF(ROW()-1<=ROWS(_xlpm.sortedPairs),INDEX(_xlpm.sortedPairs,ROW()-1,1),"")),"")} | M2: {=IFERROR(_xlfn.LET(_xlpm.pairs,_xlfn._xlws.FILTER($A$2:$D$391,($A$2:$A$391<>"")*(TRIM($D$2:$D$391)<>"")),_xlpm.uniquePairs,_xlfn.UNIQUE(_xlfn.HSTACK(INDEX(_xlpm.pairs,,1),INDEX(_xlpm.pairs,,4))),_xlpm.sortedPairs,_xlfn._xlws.SORT(_xlpm.uniquePairs,1,1),IF(ROW()-1<=ROWS(_xlpm.sortedPairs),INDEX(_xlpm.sortedPairs,ROW()-1,2),"")),"")} | N2: {=IF(OR(L2="",M2=""),"",IFERROR(INDEX($E$2:$E$391,MATCH(1,($A$2:$A$391=L2)*($D$2:$D$391=M2),0)),""))} | O2: =IF(OR(L2="",M2=""),"",SUMIFS($J$2:$J$391,$A$2:$A$391,L2,$D$2:$D$391,M2)) | Q2: {=IFERROR(INDEX($L$2:$L$391,MATCH(0,COUNTIF($Q$1:Q1,$L$2:$L$391)+IF($L$2:$L$391="",1,0),0)),"")} | R2: =IF(Q2="","",SUMIF($L$2:$L$391,Q2,$O$2:$O$391)) | S2: =IFERROR(Table3[[#This Row],[Price (€/kg)]]*HELPER!$AK$2," ")
A3: TIPA 302FG | B3: Ext. A (Out - Chillroll) | C3: PLA | D3: =IF(C3="","",IFERROR(_xlfn.XLOOKUP(C3,HELPER!$A$2:$A$76,HELPER!$B$2:$B$76,""),D3)) | E3: =IFERROR(_xlfn.XLOOKUP(D3,HELPER!$B:$B,HELPER!$C:$C,""),"") | F3: =IFERROR(_xlfn.XLOOKUP(D3,HELPER!$B:$B,HELPER!$D:$D,""),"") | G3: 8 | H3: 0.144 | I3: =IF(AND(H3<>"",IFERROR(_xlfn.XLOOKUP(D3,HELPER!$B:$B,HELPER!$E:$E,""),"")=""),"Missing price",IFERROR(_xlfn.XLOOKUP(D3,HELPER!$B:$B,HELPER!$E:$E,"")," ")) | J3: =IFERROR(H3*(IF(G3=8,I3*HELPER!$G$2,BOM!I3*HELPER!$G$3))," ") | L3: {=IFERROR(_xlfn.LET(_xlpm.pairs,_xlfn._xlws.FILTER($A$2:$D$391,($A$2:$A$391<>"")*(TRIM($D$2:$D$391)<>"")),_xlpm.uniquePairs,_xlfn.UNIQUE(_xlfn.HSTACK(INDEX(_xlpm.pairs,,1),INDEX(_xlpm.pairs,,4))),_xlpm.sortedPairs,_xlfn._xlws.SORT(_xlpm.uniquePairs,1,1),IF(ROW()-1<=ROWS(_xlpm.sortedPairs),INDEX(_xlpm.sortedPairs,ROW()-1,1),"")),"")} | M3: {=IFERROR(_xlfn.LET(_xlpm.pairs,_xlfn._xlws.FILTER($A$2:$D$391,($A$2:$A$391<>"")*(TRIM($D$2:$D$391)<>"")),_xlpm.uniquePairs,_xlfn.UNIQUE(_xlfn.HSTACK(INDEX(_xlpm.pairs,,1),INDEX(_xlpm.pairs,,4))),_xlpm.sortedPairs,_xlfn._xlws.SORT(_xlpm.uniquePairs,1,1),IF(ROW()-1<=ROWS(_xlpm.sortedPairs),INDEX(_xlpm.sortedPairs,ROW()-1,2),"")),"")} | N3: {=IF(OR(L3="",M3=""),"",IFERROR(INDEX($E$2:$E$391,MATCH(1,($A$2:$A$391=L3)*($D$2:$D$391=M3),0)),""))} | O3: =IF(OR(L3="",M3=""),"",SUMIFS($J$2:$J$391,$A$2:$A$391,L3,$D$2:$D$391,M3)) | Q3: {=IFERROR(INDEX($L$2:$L$391,MATCH(0,COUNTIF($Q$1:Q2,$L$2:$L$391)+IF($L$2:$L$391="",1,0),0)),"")} | R3: =IF(Q3="","",SUMIF($L$2:$L$391,Q3,$O$2:$O$391)) | S3: =IFERROR(Table3[[#This Row],[Price (€/kg)]]*HELPER!$AK$2," ")
A4: TIPA 302FG | B4: Ext. A (Out - Chillroll) | C4: AB-PLA | D4: =IF(C4="","",IFERROR(_xlfn.XLOOKUP(C4,HELPER!$A$2:$A$76,HELPER!$B$2:$B$76,""),D4)) | E4: =IFERROR(_xlfn.XLOOKUP(D4,HELPER!$B:$B,HELPER!$C:$C,""),"") | F4: =IFERROR(_xlfn.XLOOKUP(D4,HELPER!$B:$B,HELPER!$D:$D,""),"") | G4: 8 | H4: 0.015 | I4: =IF(AND(H4<>"",IFERROR(_xlfn.XLOOKUP(D4,HELPER!$B:$B,HELPER!$E:$E,""),"")=""),"Missing price",IFERROR(_xlfn.XLOOKUP(D4,HELPER!$B:$B,HELPER!$E:$E,"")," ")) | J4: =IFERROR(H4*(IF(G4=8,I4*HELPER!$G$2,BOM!I4*HELPER!$G$3))," ") | L4: {=IFERROR(_xlfn.LET(_xlpm.pairs,_xlfn._xlws.FILTER($A$2:$D$391,($A$2:$A$391<>"")*(TRIM($D$2:$D$391)<>"")),_xlpm.uniquePairs,_xlfn.UNIQUE(_xlfn.HSTACK(INDEX(_xlpm.pairs,,1),INDEX(_xlpm.pairs,,4))),_xlpm.sortedPairs,_xlfn._xlws.SORT(_xlpm.uniquePairs,1,1),IF(ROW()-1<=ROWS(_xlpm.sortedPairs),INDEX(_xlpm.sortedPairs,ROW()-1,1),"")),"")} | M4: {=IFERROR(_xlfn.LET(_xlpm.pairs,_xlfn._xlws.FILTER($A$2:$D$391,($A$2:$A$391<>"")*(TRIM($D$2:$D$391)<>"")),_xlpm.uniquePairs,_xlfn.UNIQUE(_xlfn.HSTACK(INDEX(_xlpm.pairs,,1),INDEX(_xlpm.pairs,,4))),_xlpm.sortedPairs,_xlfn._xlws.SORT(_xlpm.uniquePairs,1,1),IF(ROW()-1<=ROWS(_xlpm.sortedPairs),INDEX(_xlpm.sortedPairs,ROW()-1,2),"")),"")} | N4: {=IF(OR(L4="",M4=""),"",IFERROR(INDEX($E$2:$E$391,MATCH(1,($A$2:$A$391=L4)*($D$2:$D$391=M4),0)),""))} | O4: =IF(OR(L4="",M4=""),"",SUMIFS($J$2:$J$391,$A$2:$A$391,L4,$D$2:$D$391,M4)) | Q4: {=IFERROR(INDEX($L$2:$L$391,MATCH(0,COUNTIF($Q$1:Q3,$L$2:$L$391)+IF($L$2:$L$391="",1,0),0)),"")} | R4: =IF(Q4="","",SUMIF($L$2:$L$391,Q4,$O$2:$O$391)) | S4: =IFERROR(Table3[[#This Row],[Price (€/kg)]]*HELPER!$AK$2," ")
A5: TIPA 302FG | B5: Ext. A (Out - Chillroll) | C5: AO-PBS | D5: =IF(C5="","",IFERROR(_xlfn.XLOOKUP(C5,HELPER!$A$2:$A$76,HELPER!$B$2:$B$76,""),D5)) | E5: =IFERROR(_xlfn.XLOOKUP(D5,HELPER!$B:$B,HELPER!$C:$C,""),"") | F5: =IFERROR(_xlfn.XLOOKUP(D5,HELPER!$B:$B,HELPER!$D:$D,""),"") | G5: 8 | H5: 0.015 | I5: =IF(AND(H5<>"",IFERROR(_xlfn.XLOOKUP(D5,HELPER!$B:$B,HELPER!$E:$E,""),"")=""),"Missing price",IFERROR(_xlfn.XLOOKUP(D5,HELPER!$B:$B,HELPER!$E:$E,"")," ")) | J5: =IFERROR(H5*(IF(G5=8,I5*HELPER!$G$2,BOM!I5*HELPER!$G$3))," ") | L5: {=IFERROR(_xlfn.LET(_xlpm.pairs,_xlfn._xlws.FILTER($A$2:$D$391,($A$2:$A$391<>"")*(TRIM($D$2:$D$391)<>"")),_xlpm.uniquePairs,_xlfn.UNIQUE(_xlfn.HSTACK(INDEX(_xlpm.pairs,,1),INDEX(_xlpm.pairs,,4))),_xlpm.sortedPairs,_xlfn._xlws.SORT(_xlpm.uniquePairs,1,1),IF(ROW()-1<=ROWS(_xlpm.sortedPairs),INDEX(_xlpm.sortedPairs,ROW()-1,1),"")),"")} | M5: {=IFERROR(_xlfn.LET(_xlpm.pairs,_xlfn._xlws.FILTER($A$2:$D$391,($A$2:$A$391<>"")*(TRIM($D$2:$D$391)<>"")),_xlpm.uniquePairs,_xlfn.UNIQUE(_xlfn.HSTACK(INDEX(_xlpm.pairs,,1),INDEX(_xlpm.pairs,,4))),_xlpm.sortedPairs,_xlfn._xlws.SORT(_xlpm.uniquePairs,1,1),IF(ROW()-1<=ROWS(_xlpm.sortedPairs),INDEX(_xlpm.sortedPairs,ROW()-1,2),"")),"")} | N5: {=IF(OR(L5="",M5=""),"",IFERROR(INDEX($E$2:$E$391,MATCH(1,($A$2:$A$391=L5)*($D$2:$D$391=M5),0)),""))} | O5: =IF(OR(L5="",M5=""),"",SUMIFS($J$2:$J$391,$A$2:$A$391,L5,$D$2:$D$391,M5)) | Q5: {=IFERROR(INDEX($L$2:$L$391,MATCH(0,COUNTIF($Q$1:Q4,$L$2:$L$391)+IF($L$2:$L$391="",1,0),0)),"")} | R5: =IF(Q5="","",SUMIF($L$2:$L$391,Q5,$O$2:$O$391)) | S5: =IFERROR(Table3[[#This Row],[Price (€/kg)]]*HELPER!$AK$2," ")
A6: TIPA 302FG | B6: Ext. A (Out - Chillroll) | D6: =IF(C6="","",IFERROR(_xlfn.XLOOKUP(C6,HELPER!$A$2:$A$76,HELPER!$B$2:$B$76,""),D6)) | E6: =IFERROR(_xlfn.XLOOKUP(D6,HELPER!$B:$B,HELPER!$C:$C,""),"") | F6: =IFERROR(_xlfn.XLOOKUP(D6,HELPER!$B:$B,HELPER!$D:$D,""),"") | G6: 8 | I6: =IF(AND(H6<>"",IFERROR(_xlfn.XLOOKUP(D6,HELPER!$B:$B,HELPER!$E:$E,""),"")=""),"Missing price",IFERROR(_xlfn.XLOOKUP(D6,HELPER!$B:$B,HELPER!$E:$E,"")," ")) | J6: =IFERROR(H6*(IF(G6=8,I6*HELPER!$G$2,BOM!I6*HELPER!$G$3))," ") | L6: {=IFERROR(_xlfn.LET(_xlpm.pairs,_xlfn._xlws.FILTER($A$2:$D$391,($A$2:$A$391<>"")*(TRIM($D$2:$D$391)<>"")),_xlpm.uniquePairs,_xlfn.UNIQUE(_xlfn.HSTACK(INDEX(_xlpm.pairs,,1),INDEX(_xlpm.pairs,,4))),_xlpm.sortedPairs,_xlfn._xlws.SORT(_xlpm.uniquePairs,1,1),IF(ROW()-1<=ROWS(_xlpm.sortedPairs),INDEX(_xlpm.sortedPairs,ROW()-1,1),"")),"")} | M6: {=IFERROR(_xlfn.LET(_xlpm.pairs,_xlfn._xlws.FILTER($A$2:$D$391,($A$2:$A$391<>"")*(TRIM($D$2:$D$391)<>"")),_xlpm.uniquePairs,_xlfn.UNIQUE(_xlfn.HSTACK(INDEX(_xlpm.pairs,,1),INDEX(_xlpm.pairs,,4))),_xlpm.sortedPairs,_xlfn._xlws.SORT(_xlpm.uniquePairs,1,1),IF(ROW()-1<=ROWS(_xlpm.sortedPairs),INDEX(_xlpm.sortedPairs,ROW()-1,2),"")),"")} | N6: {=IF(OR(L6="",M6=""),"",IFERROR(INDEX($E$2:$E$391,MATCH(1,($A$2:$A$391=L6)*($D$2:$D$391=M6),0)),""))} | O6: =IF(OR(L6="",M6=""),"",SUMIFS($J$2:$J$391,$A$2:$A$391,L6,$D$2:$D$391,M6)) | Q6: {=IFERROR(INDEX($L$2:$L$391,MATCH(0,COUNTIF($Q$1:Q5,$L$2:$L$391)+IF($L$2:$L$391="",1,0),0)),"")} | R6: =IF(Q6="","",SUMIF($L$2:$L$391,Q6,$O$2:$O$391)) | S6: =IFERROR(Table3[[#This Row],[Price (€/kg)]]*HELPER!$AK$2," ")
A7: TIPA 302FG | B7: Ext. A (Out - Chillroll) | D7: =IF(C7="","",IFERROR(_xlfn.XLOOKUP(C7,HELPER!$A$2:$A$76,HELPER!$B$2:$B$76,""),D7)) | E7: =IFERROR(_xlfn.XLOOKUP(D7,HELPER!$B:$B,HELPER!$C:$C,""),"") | F7: =IFERROR(_xlfn.XLOOKUP(D7,HELPER!$B:$B,HELPER!$D:$D,""),"") | G7: 8 | I7: =IF(AND(H7<>"",IFERROR(_xlfn.XLOOKUP(D7,HELPER!$B:$B,HELPER!$E:$E,""),"")=""),"Missing price",IFERROR(_xlfn.XLOOKUP(D7,HELPER!$B:$B,HELPER!$E:$E,"")," ")) | J7: =IFERROR(H7*(IF(G7=8,I7*HELPER!$G$2,BOM!I7*HELPER!$G$3))," ") | L7: {=IFERROR(_xlfn.LET(_xlpm.pairs,_xlfn._xlws.FILTER($A$2:$D$391,($A$2:$A$391<>"")*(TRIM($D$2:$D$391)<>"")),_xlpm.uniquePairs,_xlfn.UNIQUE(_xlfn.HSTACK(INDEX(_xlpm.pairs,,1),INDEX(_xlpm.pairs,,4))),_xlpm.sortedPairs,_xlfn._xlws.SORT(_xlpm.uniquePairs,1,1),IF(ROW()-1<=ROWS(_xlpm.sortedPairs),INDEX(_xlpm.sortedPairs,ROW()-1,1),"")),"")} | M7: {=IFERROR(_xlfn.LET(_xlpm.pairs,_xlfn._xlws.FILTER($A$2:$D$391,($A$2:$A$391<>"")*(TRIM($D$2:$D$391)<>"")),_xlpm.uniquePairs,_xlfn.UNIQUE(_xlfn.HSTACK(INDEX(_xlpm.pairs,,1),INDEX(_xlpm.pairs,,4))),_xlpm.sortedPairs,_xlfn._xlws.SORT(_xlpm.uniquePairs,1,1),IF(ROW()-1<=ROWS(_xlpm.sortedPairs),INDEX(_xlpm.sortedPairs,ROW()-1,2),"")),"")} | N7: {=IF(OR(L7="",M7=""),"",IFERROR(INDEX($E$2:$E$391,MATCH(1,($A$2:$A$391=L7)*($D$2:$D$391=M7),0)),""))} | O7: =IF(OR(L7="",M7=""),"",SUMIFS($J$2:$J$391,$A$2:$A$391,L7,$D$2:$D$391,M7)) | Q7: {=IFERROR(INDEX($L$2:$L$391,MATCH(0,COUNTIF($Q$1:Q6,$L$2:$L$391)+IF($L$2:$L$391="",1,0),0)),"")} | R7: =IF(Q7="","",SUMIF($L$2:$L$391,Q7,$O$2:$O$391)) | S7: =IFERROR(Table3[[#This Row],[Price (€/kg)]]*HELPER!$AK$2," ")
A8: TIPA 302FG | B8: Ext. A (Out - Chillroll) | D8: =IF(C8="","",IFERROR(_xlfn.XLOOKUP(C8,HELPER!$A$2:$A$76,HELPER!$B$2:$B$76,""),D8)) | E8: =IFERROR(_xlfn.XLOOKUP(D8,HELPER!$B:$B,HELPER!$C:$C,""),"") | F8: =IFERROR(_xlfn.XLOOKUP(D8,HELPER!$B:$B,HELPER!$D:$D,""),"") | G8: 8 | I8: =IF(AND(H8<>"",IFERROR(_xlfn.XLOOKUP(D8,HELPER!$B:$B,HELPER!$E:$E,""),"")=""),"Missing price",IFERROR(_xlfn.XLOOKUP(D8,HELPER!$B:$B,HELPER!$E:$E,"")," ")) | J8: =IFERROR(H8*(IF(G8=8,I8*HELPER!$G$2,BOM!I8*HELPER!$G$3))," ") | L8: {=IFERROR(_xlfn.LET(_xlpm.pairs,_xlfn._xlws.FILTER($A$2:$D$391,($A$2:$A$391<>"")*(TRIM($D$2:$D$391)<>"")),_xlpm.uniquePairs,_xlfn.UNIQUE(_xlfn.HSTACK(INDEX(_xlpm.pairs,,1),INDEX(_xlpm.pairs,,4))),_xlpm.sortedPairs,_xlfn._xlws.SORT(_xlpm.uniquePairs,1,1),IF(ROW()-1<=ROWS(_xlpm.sortedPairs),INDEX(_xlpm.sortedPairs,ROW()-1,1),"")),"")} | M8: {=IFERROR(_xlfn.LET(_xlpm.pairs,_xlfn._xlws.FILTER($A$2:$D$391,($A$2:$A$391<>"")*(TRIM($D$2:$D$391)<>"")),_xlpm.uniquePairs,_xlfn.UNIQUE(_xlfn.HSTACK(INDEX(_xlpm.pairs,,1),INDEX(_xlpm.pairs,,4))),_xlpm.sortedPairs,_xlfn._xlws.SORT(_xlpm.uniquePairs,1,1),IF(ROW()-1<=ROWS(_xlpm.sortedPairs),INDEX(_xlpm.sortedPairs,ROW()-1,2),"")),"")} | N8: {=IF(OR(L8="",M8=""),"",IFERROR(INDEX($E$2:$E$391,MATCH(1,($A$2:$A$391=L8)*($D$2:$D$391=M8),0)),""))} | O8: =IF(OR(L8="",M8=""),"",SUMIFS($J$2:$J$391,$A$2:$A$391,L8,$D$2:$D$391,M8)) | Q8: {=IFERROR(INDEX($L$2:$L$391,MATCH(0,COUNTIF($Q$1:Q7,$L$2:$L$391)+IF($L$2:$L$391="",1,0),0)),"")} | R8: =IF(Q8="","",SUMIF($L$2:$L$391,Q8,$O$2:$O$391)) | S8: =IFERROR(Table3[[#This Row],[Price (€/kg)]]*HELPER!$AK$2," ")
A9: TIPA 302FG | B9: Ext. A (Out - Chillroll) | D9: =IF(C9="","",IFERROR(_xlfn.XLOOKUP(C9,HELPER!$A$2:$A$76,HELPER!$B$2:$B$76,""),D9)) | E9: =IFERROR(_xlfn.XLOOKUP(D9,HELPER!$B:$B,HELPER!$C:$C,""),"") | F9: =IFERROR(_xlfn.XLOOKUP(D9,HELPER!$B:$B,HELPER!$D:$D,""),"") | G9: 8 | I9: =IF(AND(H9<>"",IFERROR(_xlfn.XLOOKUP(D9,HELPER!$B:$B,HELPER!$E:$E,""),"")=""),"Missing price",IFERROR(_xlfn.XLOOKUP(D9,HELPER!$B:$B,HELPER!$E:$E,"")," ")) | J9: =IFERROR(H9*(IF(G9=8,I9*HELPER!$G$2,BOM!I9*HELPER!$G$3))," ") | L9: {=IFERROR(_xlfn.LET(_xlpm.pairs,_xlfn._xlws.FILTER($A$2:$D$391,($A$2:$A$391<>"")*(TRIM($D$2:$D$391)<>"")),_xlpm.uniquePairs,_xlfn.UNIQUE(_xlfn.HSTACK(INDEX(_xlpm.pairs,,1),INDEX(_xlpm.pairs,,4))),_xlpm.sortedPairs,_xlfn._xlws.SORT(_xlpm.uniquePairs,1,1),IF(ROW()-1<=ROWS(_xlpm.sortedPairs),INDEX(_xlpm.sortedPairs,ROW()-1,1),"")),"")} | M9: {=IFERROR(_xlfn.LET(_xlpm.pairs,_xlfn._xlws.FILTER($A$2:$D$391,($A$2:$A$391<>"")*(TRIM($D$2:$D$391)<>"")),_xlpm.uniquePairs,_xlfn.UNIQUE(_xlfn.HSTACK(INDEX(_xlpm.pairs,,1),INDEX(_xlpm.pairs,,4))),_xlpm.sortedPairs,_xlfn._xlws.SORT(_xlpm.uniquePairs,1,1),IF(ROW()-1<=ROWS(_xlpm.sortedPairs),INDEX(_xlpm.sortedPairs,ROW()-1,2),"")),"")} | N9: {=IF(OR(L9="",M9=""),"",IFERROR(INDEX($E$2:$E$391,MATCH(1,($A$2:$A$391=L9)*($D$2:$D$391=M9),0)),""))} | O9: =IF(OR(L9="",M9=""),"",SUMIFS($J$2:$J$391,$A$2:$A$391,L9,$D$2:$D$391,M9)) | Q9: {=IFERROR(INDEX($L$2:$L$391,MATCH(0,COUNTIF($Q$1:Q8,$L$2:$L$391)+IF($L$2:$L$391="",1,0),0)),"")} | R9: =IF(Q9="","",SUMIF($L$2:$L$391,Q9,$O$2:$O$391)) | S9: =IFERROR(Table3[[#This Row],[Price (€/kg)]]*HELPER!$AK$2," ")
A10: TIPA 302FG | B10: Ext. A (Out - Chillroll) | D10: =IF(C10="","",IFERROR(_xlfn.XLOOKUP(C10,HELPER!$A$2:$A$76,HELPER!$B$2:$B$76,""),D10)) | E10: =IFERROR(_xlfn.XLOOKUP(D10,HELPER!$B:$B,HELPER!$C:$C,""),"") | F10: =IFERROR(_xlfn.XLOOKUP(D10,HELPER!$B:$B,HELPER!$D:$D,""),"") | G10: 8 | I10: =IF(AND(H10<>"",IFERROR(_xlfn.XLOOKUP(D10,HELPER!$B:$B,HELPER!$E:$E,""),"")=""),"Missing price",IFERROR(_xlfn.XLOOKUP(D10,HELPER!$B:$B,HELPER!$E:$E,"")," ")) | J10: =IFERROR(H10*(IF(G10=8,I10*HELPER!$G$2,BOM!I10*HELPER!$G$3))," ") | L10: {=IFERROR(_xlfn.LET(_xlpm.pairs,_xlfn._xlws.FILTER($A$2:$D$391,($A$2:$A$391<>"")*(TRIM($D$2:$D$391)<>"")),_xlpm.uniquePairs,_xlfn.UNIQUE(_xlfn.HSTACK(INDEX(_xlpm.pairs,,1),INDEX(_xlpm.pairs,,4))),_xlpm.sortedPairs,_xlfn._xlws.SORT(_xlpm.uniquePairs,1,1),IF(ROW()-1<=ROWS(_xlpm.sortedPairs),INDEX(_xlpm.sortedPairs,ROW()-1,1),"")),"")} | M10: {=IFERROR(_xlfn.LET(_xlpm.pairs,_xlfn._xlws.FILTER($A$2:$D$391,($A$2:$A$391<>"")*(TRIM($D$2:$D$391)<>"")),_xlpm.uniquePairs,_xlfn.UNIQUE(_xlfn.HSTACK(INDEX(_xlpm.pairs,,1),INDEX(_xlpm.pairs,,4))),_xlpm.sortedPairs,_xlfn._xlws.SORT(_xlpm.uniquePairs,1,1),IF(ROW()-1<=ROWS(_xlpm.sortedPairs),INDEX(_xlpm.sortedPairs,ROW()-1,2),"")),"")} | N10: {=IF(OR(L10="",M10=""),"",IFERROR(INDEX($E$2:$E$391,MATCH(1,($A$2:$A$391=L10)*($D$2:$D$391=M10),0)),""))} | O10: =IF(OR(L10="",M10=""),"",SUMIFS($J$2:$J$391,$A$2:$A$391,L10,$D$2:$D$391,M10)) | Q10: {=IFERROR(INDEX($L$2:$L$391,MATCH(0,COUNTIF($Q$1:Q9,$L$2:$L$391)+IF($L$2:$L$391="",1,0),0)),"")} | R10: =IF(Q10="","",SUMIF($L$2:$L$391,Q10,$O$2:$O$391)) | S10: =IFERROR(Table3[[#This Row],[Price (€/kg)]]*HELPER!$AK$2," ")
A11: TIPA 302FG | B11: Ext. A (Out - Chillroll) | D11: =IF(C11="","",IFERROR(_xlfn.XLOOKUP(C11,HELPER!$A$2:$A$76,HELPER!$B$2:$B$76,""),D11)) | E11: =IFERROR(_xlfn.XLOOKUP(D11,HELPER!$B:$B,HELPER!$C:$C,""),"") | F11: =IFERROR(_xlfn.XLOOKUP(D11,HELPER!$B:$B,HELPER!$D:$D,""),"") | G11: 8 | I11: =IF(AND(H11<>"",IFERROR(_xlfn.XLOOKUP(D11,HELPER!$B:$B,HELPER!$E:$E,""),"")=""),"Missing price",IFERROR(_xlfn.XLOOKUP(D11,HELPER!$B:$B,HELPER!$E:$E,"")," ")) | J11: =IFERROR(H11*(IF(G11=8,I11*HELPER!$G$2,BOM!I11*HELPER!$G$3))," ") | L11: {=IFERROR(_xlfn.LET(_xlpm.pairs,_xlfn._xlws.FILTER($A$2:$D$391,($A$2:$A$391<>"")*(TRIM($D$2:$D$391)<>"")),_xlpm.uniquePairs,_xlfn.UNIQUE(_xlfn.HSTACK(INDEX(_xlpm.pairs,,1),INDEX(_xlpm.pairs,,4))),_xlpm.sortedPairs,_xlfn._xlws.SORT(_xlpm.uniquePairs,1,1),IF(ROW()-1<=ROWS(_xlpm.sortedPairs),INDEX(_xlpm.sortedPairs,ROW()-1,1),"")),"")} | M11: {=IFERROR(_xlfn.LET(_xlpm.pairs,_xlfn._xlws.FILTER($A$2:$D$391,($A$2:$A$391<>"")*(TRIM($D$2:$D$391)<>"")),_xlpm.uniquePairs,_xlfn.UNIQUE(_xlfn.HSTACK(INDEX(_xlpm.pairs,,1),INDEX(_xlpm.pairs,,4))),_xlpm.sortedPairs,_xlfn._xlws.SORT(_xlpm.uniquePairs,1,1),IF(ROW()-1<=ROWS(_xlpm.sortedPairs),INDEX(_xlpm.sortedPairs,ROW()-1,2),"")),"")} | N11: {=IF(OR(L11="",M11=""),"",IFERROR(INDEX($E$2:$E$391,MATCH(1,($A$2:$A$391=L11)*($D$2:$D$391=M11),0)),""))} | O11: =IF(OR(L11="",M11=""),"",SUMIFS($J$2:$J$391,$A$2:$A$391,L11,$D$2:$D$391,M11)) | Q11: {=IFERROR(INDEX($L$2:$L$391,MATCH(0,COUNTIF($Q$1:Q10,$L$2:$L$391)+IF($L$2:$L$391="",1,0),0)),"")} | R11: =IF(Q11="","",SUMIF($L$2:$L$391,Q11,$O$2:$O$391)) | S11: =IFERROR(Table3[[#This Row],[Price (€/kg)]]*HELPER!$AK$2," ")
A12: TIPA 302FG | B12: Ext. B | D12: =IF(C12="","",IFERROR(_xlfn.XLOOKUP(C12,HELPER!$A$2:$A$76,HELPER!$B$2:$B$76,""),D12)) | E12: =IFERROR(_xlfn.XLOOKUP(D12,HELPER!$B:$B,HELPER!$C:$C,""),"") | F12: =IFERROR(_xlfn.XLOOKUP(D12,HELPER!$B:$B,HELPER!$D:$D,""),"") | G12: 8 | I12: =IF(AND(H12<>"",IFERROR(_xlfn.XLOOKUP(D12,HELPER!$B:$B,HELPER!$E:$E,""),"")=""),"Missing price",IFERROR(_xlfn.XLOOKUP(D12,HELPER!$B:$B,HELPER!$E:$E,"")," ")) | J12: =IFERROR(H12*(IF(G12=8,I12*HELPER!$G$2,BOM!I12*HELPER!$G$3))," ") | L12: {=IFERROR(_xlfn.LET(_xlpm.pairs,_xlfn._xlws.FILTER($A$2:$D$391,($A$2:$A$391<>"")*(TRIM($D$2:$D$391)<>"")),_xlpm.uniquePairs,_xlfn.UNIQUE(_xlfn.HSTACK(INDEX(_xlpm.pairs,,1),INDEX(_xlpm.pairs,,4))),_xlpm.sortedPairs,_xlfn._xlws.SORT(_xlpm.uniquePairs,1,1),IF(ROW()-1<=ROWS(_xlpm.sortedPairs),INDEX(_xlpm.sortedPairs,ROW()-1,1),"")),"")} | M12: {=IFERROR(_xlfn.LET(_xlpm.pairs,_xlfn._xlws.FILTER($A$2:$D$391,($A$2:$A$391<>"")*(TRIM($D$2:$D$391)<>"")),_xlpm.uniquePairs,_xlfn.UNIQUE(_xlfn.HSTACK(INDEX(_xlpm.pairs,,1),INDEX(_xlpm.pairs,,4))),_xlpm.sortedPairs,_xlfn._xlws.SORT(_xlpm.uniquePairs,1,1),IF(ROW()-1<=ROWS(_xlpm.sortedPairs),INDEX(_xlpm.sortedPairs,ROW()-1,2),"")),"")} | N12: {=IF(OR(L12="",M12=""),"",IFERROR(INDEX($E$2:$E$391,MATCH(1,($A$2:$A$391=L12)*($D$2:$D$391=M12),0)),""))} | O12: =IF(OR(L12="",M12=""),"",SUMIFS($J$2:$J$391,$A$2:$A$391,L12,$D$2:$D$391,M12)) | Q12: {=IFERROR(INDEX($L$2:$L$391,MATCH(0,COUNTIF($Q$1:Q11,$L$2:$L$391)+IF($L$2:$L$391="",1,0),0)),"")} | R12: =IF(Q12="","",SUMIF($L$2:$L$391,Q12,$O$2:$O$391)) | S12: =IFERROR(Table3[[#This Row],[Price (€/kg)]]*HELPER!$AK$2," ")
A13: TIPA 302FG | B13: Ext. B | D13: =IF(C13="","",IFERROR(_xlfn.XLOOKUP(C13,HELPER!$A$2:$A$76,HELPER!$B$2:$B$76,""),D13)) | E13: =IFERROR(_xlfn.XLOOKUP(D13,HELPER!$B:$B,HELPER!$C:$C,""),"") | F13: =IFERROR(_xlfn.XLOOKUP(D13,HELPER!$B:$B,HELPER!$D:$D,""),"") | G13: 24 | I13: =IF(AND(H13<>"",IFERROR(_xlfn.XLOOKUP(D13,HELPER!$B:$B,HELPER!$E:$E,""),"")=""),"Missing price",IFERROR(_xlfn.XLOOKUP(D13,HELPER!$B:$B,HELPER!$E:$E,"")," ")) | J13: =IFERROR(H13*(IF(G13=8,I13*HELPER!$G$2,BOM!I13*HELPER!$G$3))," ") | L13: {=IFERROR(_xlfn.LET(_xlpm.pairs,_xlfn._xlws.FILTER($A$2:$D$391,($A$2:$A$391<>"")*(TRIM($D$2:$D$391)<>"")),_xlpm.uniquePairs,_xlfn.UNIQUE(_xlfn.HSTACK(INDEX(_xlpm.pairs,,1),INDEX(_xlpm.pairs,,4))),_xlpm.sortedPairs,_xlfn._xlws.SORT(_xlpm.uniquePairs,1,1),IF(ROW()-1<=ROWS(_xlpm.sortedPairs),INDEX(_xlpm.sortedPairs,ROW()-1,1),"")),"")} | M13: {=IFERROR(_xlfn.LET(_xlpm.pairs,_xlfn._xlws.FILTER($A$2:$D$391,($A$2:$A$391<>"")*(TRIM($D$2:$D$391)<>"")),_xlpm.uniquePairs,_xlfn.UNIQUE(_xlfn.HSTACK(INDEX(_xlpm.pairs,,1),INDEX(_xlpm.pairs,,4))),_xlpm.sortedPairs,_xlfn._xlws.SORT(_xlpm.uniquePairs,1,1),IF(ROW()-1<=ROWS(_xlpm.sortedPairs),INDEX(_xlpm.sortedPairs,ROW()-1,2),"")),"")} | N13: {=IF(OR(L13="",M13=""),"",IFERROR(INDEX($E$2:$E$391,MATCH(1,($A$2:$A$391=L13)*($D$2:$D$391=M13),0)),""))} | O13: =IF(OR(L13="",M13=""),"",SUMIFS($J$2:$J$391,$A$2:$A$391,L13,$D$2:$D$391,M13)) | Q13: {=IFERROR(INDEX($L$2:$L$391,MATCH(0,COUNTIF($Q$1:Q12,$L$2:$L$391)+IF($L$2:$L$391="",1,0),0)),"")} | R13: =IF(Q13="","",SUMIF($L$2:$L$391,Q13,$O$2:$O$391)) | S13: =IFERROR(Table3[[#This Row],[Price (€/kg)]]*HELPER!$AK$2," ")
A14: TIPA 302FG | B14: Ext. B | D14: =IF(C14="","",IFERROR(_xlfn.XLOOKUP(C14,HELPER!$A$2:$A$76,HELPER!$B$2:$B$76,""),D14)) | E14: =IFERROR(_xlfn.XLOOKUP(D14,HELPER!$B:$B,HELPER!$C:$C,""),"") | F14: =IFERROR(_xlfn.XLOOKUP(D14,HELPER!$B:$B,HELPER!$D:$D,""),"") | G14: 24 | I14: =IF(AND(H14<>"",IFERROR(_xlfn.XLOOKUP(D14,HELPER!$B:$B,HELPER!$E:$E,""),"")=""),"Missing price",IFERROR(_xlfn.XLOOKUP(D14,HELPER!$B:$B,HELPER!$E:$E,"")," ")) | J14: =IFERROR(H14*(IF(G14=8,I14*HELPER!$G$2,BOM!I14*HELPER!$G$3))," ") | L14: {=IFERROR(_xlfn.LET(_xlpm.pairs,_xlfn._xlws.FILTER($A$2:$D$391,($A$2:$A$391<>"")*(TRIM($D$2:$D$391)<>"")),_xlpm.uniquePairs,_xlfn.UNIQUE(_xlfn.HSTACK(INDEX(_xlpm.pairs,,1),INDEX(_xlpm.pairs,,4))),_xlpm.sortedPairs,_xlfn._xlws.SORT(_xlpm.uniquePairs,1,1),IF(ROW()-1<=ROWS(_xlpm.sortedPairs),INDEX(_xlpm.sortedPairs,ROW()-1,1),"")),"")} | M14: {=IFERROR(_xlfn.LET(_xlpm.pairs,_xlfn._xlws.FILTER($A$2:$D$391,($A$2:$A$391<>"")*(TRIM($D$2:$D$391)<>"")),_xlpm.uniquePairs,_xlfn.UNIQUE(_xlfn.HSTACK(INDEX(_xlpm.pairs,,1),INDEX(_xlpm.pairs,,4))),_xlpm.sortedPairs,_xlfn._xlws.SORT(_xlpm.uniquePairs,1,1),IF(ROW()-1<=ROWS(_xlpm.sortedPairs),INDEX(_xlpm.sortedPairs,ROW()-1,2),"")),"")} | N14: {=IF(OR(L14="",M14=""),"",IFERROR(INDEX($E$2:$E$391,MATCH(1,($A$2:$A$391=L14)*($D$2:$D$391=M14),0)),""))} | O14: =IF(OR(L14="",M14=""),"",SUMIFS($J$2:$J$391,$A$2:$A$391,L14,$D$2:$D$391,M14)) | Q14: {=IFERROR(INDEX($L$2:$L$391,MATCH(0,COUNTIF($Q$1:Q13,$L$2:$L$391)+IF($L$2:$L$391="",1,0),0)),"")} | R14: =IF(Q14="","",SUMIF($L$2:$L$391,Q14,$O$2:$O$391)) | S14: =IFERROR(Table3[[#This Row],[Price (€/kg)]]*HELPER!$AK$2," ")
A15: TIPA 302FG | B15: Ext. B | D15: =IF(C15="","",IFERROR(_xlfn.XLOOKUP(C15,HELPER!$A$2:$A$76,HELPER!$B$2:$B$76,""),D15)) | E15: =IFERROR(_xlfn.XLOOKUP(D15,HELPER!$B:$B,HELPER!$C:$C,""),"") | F15: =IFERROR(_xlfn.XLOOKUP(D15,HELPER!$B:$B,HELPER!$D:$D,""),"") | G15: 24 | I15: =IF(AND(H15<>"",IFERROR(_xlfn.XLOOKUP(D15,HELPER!$B:$B,HELPER!$E:$E,""),"")=""),"Missing price",IFERROR(_xlfn.XLOOKUP(D15,HELPER!$B:$B,HELPER!$E:$E,"")," ")) | J15: =IFERROR(H15*(IF(G15=8,I15*HELPER!$G$2,BOM!I15*HELPER!$G$3))," ") | L15: {=IFERROR(_xlfn.LET(_xlpm.pairs,_xlfn._xlws.FILTER($A$2:$D$391,($A$2:$A$391<>"")*(TRIM($D$2:$D$391)<>"")),_xlpm.uniquePairs,_xlfn.UNIQUE(_xlfn.HSTACK(INDEX(_xlpm.pairs,,1),INDEX(_xlpm.pairs,,4))),_xlpm.sortedPairs,_xlfn._xlws.SORT(_xlpm.uniquePairs,1,1),IF(ROW()-1<=ROWS(_xlpm.sortedPairs),INDEX(_xlpm.sortedPairs,ROW()-1,1),"")),"")} | M15: {=IFERROR(_xlfn.LET(_xlpm.pairs,_xlfn._xlws.FILTER($A$2:$D$391,($A$2:$A$391<>"")*(TRIM($D$2:$D$391)<>"")),_xlpm.uniquePairs,_xlfn.UNIQUE(_xlfn.HSTACK(INDEX(_xlpm.pairs,,1),INDEX(_xlpm.pairs,,4))),_xlpm.sortedPairs,_xlfn._xlws.SORT(_xlpm.uniquePairs,1,1),IF(ROW()-1<=ROWS(_xlpm.sortedPairs),INDEX(_xlpm.sortedPairs,ROW()-1,2),"")),"")} | N15: {=IF(OR(L15="",M15=""),"",IFERROR(INDEX($E$2:$E$391,MATCH(1,($A$2:$A$391=L15)*($D$2:$D$391=M15),0)),""))} | O15: =IF(OR(L15="",M15=""),"",SUMIFS($J$2:$J$391,$A$2:$A$391,L15,$D$2:$D$391,M15)) | Q15: {=IFERROR(INDEX($L$2:$L$391,MATCH(0,COUNTIF($Q$1:Q14,$L$2:$L$391)+IF($L$2:$L$391="",1,0),0)),"")} | R15: =IF(Q15="","",SUMIF($L$2:$L$391,Q15,$O$2:$O$391)) | S15: =IFERROR(Table3[[#This Row],[Price (€/kg)]]*HELPER!$AK$2," ")
A16: TIPA 302FG | B16: Ext. B | C16: AO-PBS | D16: =IF(C16="","",IFERROR(_xlfn.XLOOKUP(C16,HELPER!$A$2:$A$76,HELPER!$B$2:$B$76,""),D16)) | E16: =IFERROR(_xlfn.XLOOKUP(D16,HELPER!$B:$B,HELPER!$C:$C,""),"") | F16: =IFERROR(_xlfn.XLOOKUP(D16,HELPER!$B:$B,HELPER!$D:$D,""),"") | G16: 24 | H16: 0.015 | I16: =IF(AND(H16<>"",IFERROR(_xlfn.XLOOKUP(D16,HELPER!$B:$B,HELPER!$E:$E,""),"")=""),"Missing price",IFERROR(_xlfn.XLOOKUP(D16,HELPER!$B:$B,HELPER!$E:$E,"")," ")) | J16: =IFERROR(H16*(IF(G16=8,I16*HELPER!$G$2,BOM!I16*HELPER!$G$3))," ") | L16: {=IFERROR(_xlfn.LET(_xlpm.pairs,_xlfn._xlws.FILTER($A$2:$D$391,($A$2:$A$391<>"")*(TRIM($D$2:$D$391)<>"")),_xlpm.uniquePairs,_xlfn.UNIQUE(_xlfn.HSTACK(INDEX(_xlpm.pairs,,1),INDEX(_xlpm.pairs,,4))),_xlpm.sortedPairs,_xlfn._xlws.SORT(_xlpm.uniquePairs,1,1),IF(ROW()-1<=ROWS(_xlpm.sortedPairs),INDEX(_xlpm.sortedPairs,ROW()-1,1),"")),"")} | M16: {=IFERROR(_xlfn.LET(_xlpm.pairs,_xlfn._xlws.FILTER($A$2:$D$391,($A$2:$A$391<>"")*(TRIM($D$2:$D$391)<>"")),_xlpm.uniquePairs,_xlfn.UNIQUE(_xlfn.HSTACK(INDEX(_xlpm.pairs,,1),INDEX(_xlpm.pairs,,4))),_xlpm.sortedPairs,_xlfn._xlws.SORT(_xlpm.uniquePairs,1,1),IF(ROW()-1<=ROWS(_xlpm.sortedPairs),INDEX(_xlpm.sortedPairs,ROW()-1,2),"")),"")} | N16: {=IF(OR(L16="",M16=""),"",IFERROR(INDEX($E$2:$E$391,MATCH(1,($A$2:$A$391=L16)*($D$2:$D$391=M16),0)),""))} | O16: =IF(OR(L16="",M16=""),"",SUMIFS($J$2:$J$391,$A$2:$A$391,L16,$D$2:$D$391,M16)) | Q16: {=IFERROR(INDEX($L$2:$L$391,MATCH(0,COUNTIF($Q$1:Q15,$L$2:$L$391)+IF($L$2:$L$391="",1,0),0)),"")} | R16: =IF(Q16="","",SUMIF($L$2:$L$391,Q16,$O$2:$O$391)) | S16: =IFERROR(Table3[[#This Row],[Price (€/kg)]]*HELPER!$AK$2," ")
A17: TIPA 302FG | B17: Ext. B | D17: =IF(C17="","",IFERROR(_xlfn.XLOOKUP(C17,HELPER!$A$2:$A$76,HELPER!$B$2:$B$76,""),D17)) | E17: =IFERROR(_xlfn.XLOOKUP(D17,HELPER!$B:$B,HELPER!$C:$C,""),"") | F17: =IFERROR(_xlfn.XLOOKUP(D17,HELPER!$B:$B,HELPER!$D:$D,""),"") | G17: 24 | I17: =IF(AND(H17<>"",IFERROR(_xlfn.XLOOKUP(D17,HELPER!$B:$B,HELPER!$E:$E,""),"")=""),"Missing price",IFERROR(_xlfn.XLOOKUP(D17,HELPER!$B:$B,HELPER!$E:$E,"")," ")) | J17: =IFERROR(H17*(IF(G17=8,I17*HELPER!$G$2,BOM!I17*HELPER!$G$3))," ") | L17: {=IFERROR(_xlfn.LET(_xlpm.pairs,_xlfn._xlws.FILTER($A$2:$D$391,($A$2:$A$391<>"")*(TRIM($D$2:$D$391)<>"")),_xlpm.uniquePairs,_xlfn.UNIQUE(_xlfn.HSTACK(INDEX(_xlpm.pairs,,1),INDEX(_xlpm.pairs,,4))),_xlpm.sortedPairs,_xlfn._xlws.SORT(_xlpm.uniquePairs,1,1),IF(ROW()-1<=ROWS(_xlpm.sortedPairs),INDEX(_xlpm.sortedPairs,ROW()-1,1),"")),"")} | M17: {=IFERROR(_xlfn.LET(_xlpm.pairs,_xlfn._xlws.FILTER($A$2:$D$391,($A$2:$A$391<>"")*(TRIM($D$2:$D$391)<>"")),_xlpm.uniquePairs,_xlfn.UNIQUE(_xlfn.HSTACK(INDEX(_xlpm.pairs,,1),INDEX(_xlpm.pairs,,4))),_xlpm.sortedPairs,_xlfn._xlws.SORT(_xlpm.uniquePairs,1,1),IF(ROW()-1<=ROWS(_xlpm.sortedPairs),INDEX(_xlpm.sortedPairs,ROW()-1,2),"")),"")} | N17: {=IF(OR(L17="",M17=""),"",IFERROR(INDEX($E$2:$E$391,MATCH(1,($A$2:$A$391=L17)*($D$2:$D$391=M17),0)),""))} | O17: =IF(OR(L17="",M17=""),"",SUMIFS($J$2:$J$391,$A$2:$A$391,L17,$D$2:$D$391,M17)) | Q17: {=IFERROR(INDEX($L$2:$L$391,MATCH(0,COUNTIF($Q$1:Q16,$L$2:$L$391)+IF($L$2:$L$391="",1,0),0)),"")} | R17: =IF(Q17="","",SUMIF($L$2:$L$391,Q17,$O$2:$O$391)) | S17: =IFERROR(Table3[[#This Row],[Price (€/kg)]]*HELPER!$AK$2," ")
A18: TIPA 302FG | B18: Ext. B | C18: PBAT | D18: =IF(C18="","",IFERROR(_xlfn.XLOOKUP(C18,HELPER!$A$2:$A$76,HELPER!$B$2:$B$76,""),D18)) | E18: =IFERROR(_xlfn.XLOOKUP(D18,HELPER!$B:$B,HELPER!$C:$C,""),"") | F18: =IFERROR(_xlfn.XLOOKUP(D18,HELPER!$B:$B,HELPER!$D:$D,""),"") | G18: 24 | H18: 0.985 | I18: =IF(AND(H18<>"",IFERROR(_xlfn.XLOOKUP(D18,HELPER!$B:$B,HELPER!$E:$E,""),"")=""),"Missing price",IFERROR(_xlfn.XLOOKUP(D18,HELPER!$B:$B,HELPER!$E:$E,"")," ")) | J18: =IFERROR(H18*(IF(G18=8,I18*HELPER!$G$2,BOM!I18*HELPER!$G$3))," ") | L18: {=IFERROR(_xlfn.LET(_xlpm.pairs,_xlfn._xlws.FILTER($A$2:$D$391,($A$2:$A$391<>"")*(TRIM($D$2:$D$391)<>"")),_xlpm.uniquePairs,_xlfn.UNIQUE(_xlfn.HSTACK(INDEX(_xlpm.pairs,,1),INDEX(_xlpm.pairs,,4))),_xlpm.sortedPairs,_xlfn._xlws.SORT(_xlpm.uniquePairs,1,1),IF(ROW()-1<=ROWS(_xlpm.sortedPairs),INDEX(_xlpm.sortedPairs,ROW()-1,1),"")),"")} | M18: {=IFERROR(_xlfn.LET(_xlpm.pairs,_xlfn._xlws.FILTER($A$2:$D$391,($A$2:$A$391<>"")*(TRIM($D$2:$D$391)<>"")),_xlpm.uniquePairs,_xlfn.UNIQUE(_xlfn.HSTACK(INDEX(_xlpm.pairs,,1),INDEX(_xlpm.pairs,,4))),_xlpm.sortedPairs,_xlfn._xlws.SORT(_xlpm.uniquePairs,1,1),IF(ROW()-1<=ROWS(_xlpm.sortedPairs),INDEX(_xlpm.sortedPairs,ROW()-1,2),"")),"")} | N18: {=IF(OR(L18="",M18=""),"",IFERROR(INDEX($E$2:$E$391,MATCH(1,($A$2:$A$391=L18)*($D$2:$D$391=M18),0)),""))} | O18: =IF(OR(L18="",M18=""),"",SUMIFS($J$2:$J$391,$A$2:$A$391,L18,$D$2:$D$391,M18)) | Q18: {=IFERROR(INDEX($L$2:$L$391,MATCH(0,COUNTIF($Q$1:Q17,$L$2:$L$391)+IF($L$2:$L$391="",1,0),0)),"")} | R18: =IF(Q18="","",SUMIF($L$2:$L$391,Q18,$O$2:$O$391)) | S18: =IFERROR(Table3[[#This Row],[Price (€/kg)]]*HELPER!$AK$2," ")
A19: TIPA 302FG | B19: Ext. B | D19: =IF(C19="","",IFERROR(_xlfn.XLOOKUP(C19,HELPER!$A$2:$A$76,HELPER!$B$2:$B$76,""),D19)) | E19: =IFERROR(_xlfn.XLOOKUP(D19,HELPER!$B:$B,HELPER!$C:$C,""),"") | F19: =IFERROR(_xlfn.XLOOKUP(D19,HELPER!$B:$B,HELPER!$D:$D,""),"") | G19: 24 | I19: =IF(AND(H19<>"",IFERROR(_xlfn.XLOOKUP(D19,HELPER!$B:$B,HELPER!$E:$E,""),"")=""),"Missing price",IFERROR(_xlfn.XLOOKUP(D19,HELPER!$B:$B,HELPER!$E:$E,"")," ")) | J19: =IFERROR(H19*(IF(G19=8,I19*HELPER!$G$2,BOM!I19*HELPER!$G$3))," ") | L19: {=IFERROR(_xlfn.LET(_xlpm.pairs,_xlfn._xlws.FILTER($A$2:$D$391,($A$2:$A$391<>"")*(TRIM($D$2:$D$391)<>"")),_xlpm.uniquePairs,_xlfn.UNIQUE(_xlfn.HSTACK(INDEX(_xlpm.pairs,,1),INDEX(_xlpm.pairs,,4))),_xlpm.sortedPairs,_xlfn._xlws.SORT(_xlpm.uniquePairs,1,1),IF(ROW()-1<=ROWS(_xlpm.sortedPairs),INDEX(_xlpm.sortedPairs,ROW()-1,1),"")),"")} | M19: {=IFERROR(_xlfn.LET(_xlpm.pairs,_xlfn._xlws.FILTER($A$2:$D$391,($A$2:$A$391<>"")*(TRIM($D$2:$D$391)<>"")),_xlpm.uniquePairs,_xlfn.UNIQUE(_xlfn.HSTACK(INDEX(_xlpm.pairs,,1),INDEX(_xlpm.pairs,,4))),_xlpm.sortedPairs,_xlfn._xlws.SORT(_xlpm.uniquePairs,1,1),IF(ROW()-1<=ROWS(_xlpm.sortedPairs),INDEX(_xlpm.sortedPairs,ROW()-1,2),"")),"")} | N19: {=IF(OR(L19="",M19=""),"",IFERROR(INDEX($E$2:$E$391,MATCH(1,($A$2:$A$391=L19)*($D$2:$D$391=M19),0)),""))} | O19: =IF(OR(L19="",M19=""),"",SUMIFS($J$2:$J$391,$A$2:$A$391,L19,$D$2:$D$391,M19)) | Q19: {=IFERROR(INDEX($L$2:$L$391,MATCH(0,COUNTIF($Q$1:Q18,$L$2:$L$391)+IF($L$2:$L$391="",1,0),0)),"")} | R19: =IF(Q19="","",SUMIF($L$2:$L$391,Q19,$O$2:$O$391)) | S19: =IFERROR(Table3[[#This Row],[Price (€/kg)]]*HELPER!$AK$2," ")
A20: TIPA 302FG | B20: Ext. B | D20: =IF(C20="","",IFERROR(_xlfn.XLOOKUP(C20,HELPER!$A$2:$A$76,HELPER!$B$2:$B$76,""),D20)) | E20: =IFERROR(_xlfn.XLOOKUP(D20,HELPER!$B:$B,HELPER!$C:$C,""),"") | F20: =IFERROR(_xlfn.XLOOKUP(D20,HELPER!$B:$B,HELPER!$D:$D,""),"") | G20: 24 | I20: =IF(AND(H20<>"",IFERROR(_xlfn.XLOOKUP(D20,HELPER!$B:$B,HELPER!$E:$E,""),"")=""),"Missing price",IFERROR(_xlfn.XLOOKUP(D20,HELPER!$B:$B,HELPER!$E:$E,"")," ")) | J20: =IFERROR(H20*(IF(G20=8,I20*HELPER!$G$2,BOM!I20*HELPER!$G$3))," ") | L20: {=IFERROR(_xlfn.LET(_xlpm.pairs,_xlfn._xlws.FILTER($A$2:$D$391,($A$2:$A$391<>"")*(TRIM($D$2:$D$391)<>"")),_xlpm.uniquePairs,_xlfn.UNIQUE(_xlfn.HSTACK(INDEX(_xlpm.pairs,,1),INDEX(_xlpm.pairs,,4))),_xlpm.sortedPairs,_xlfn._xlws.SORT(_xlpm.uniquePairs,1,1),IF(ROW()-1<=ROWS(_xlpm.sortedPairs),INDEX(_xlpm.sortedPairs,ROW()-1,1),"")),"")} | M20: {=IFERROR(_xlfn.LET(_xlpm.pairs,_xlfn._xlws.FILTER($A$2:$D$391,($A$2:$A$391<>"")*(TRIM($D$2:$D$391)<>"")),_xlpm.uniquePairs,_xlfn.UNIQUE(_xlfn.HSTACK(INDEX(_xlpm.pairs,,1),INDEX(_xlpm.pairs,,4))),_xlpm.sortedPairs,_xlfn._xlws.SORT(_xlpm.uniquePairs,1,1),IF(ROW()-1<=ROWS(_xlpm.sortedPairs),INDEX(_xlpm.sortedPairs,ROW()-1,2),"")),"")} | N20: {=IF(OR(L20="",M20=""),"",IFERROR(INDEX($E$2:$E$391,MATCH(1,($A$2:$A$391=L20)*($D$2:$D$391=M20),0)),""))} | O20: =IF(OR(L20="",M20=""),"",SUMIFS($J$2:$J$391,$A$2:$A$391,L20,$D$2:$D$391,M20)) | Q20: {=IFERROR(INDEX($L$2:$L$391,MATCH(0,COUNTIF($Q$1:Q19,$L$2:$L$391)+IF($L$2:$L$391="",1,0),0)),"")} | R20: =IF(Q20="","",SUMIF($L$2:$L$391,Q20,$O$2:$O$391)) | S20: =IFERROR(Table3[[#This Row],[Price (€/kg)]]*HELPER!$AK$2," ")
A21: TIPA 302FG | B21: Ext. B | D21: =IF(C21="","",IFERROR(_xlfn.XLOOKUP(C21,HELPER!$A$2:$A$76,HELPER!$B$2:$B$76,""),D21)) | E21: =IFERROR(_xlfn.XLOOKUP(D21,HELPER!$B:$B,HELPER!$C:$C,""),"") | F21: =IFERROR(_xlfn.XLOOKUP(D21,HELPER!$B:$B,HELPER!$D:$D,""),"") | G21: 24 | I21: =IF(AND(H21<>"",IFERROR(_xlfn.XLOOKUP(D21,HELPER!$B:$B,HELPER!$E:$E,""),"")=""),"Missing price",IFERROR(_xlfn.XLOOKUP(D21,HELPER!$B:$B,HELPER!$E:$E,"")," ")) | J21: =IFERROR(H21*(IF(G21=8,I21*HELPER!$G$2,BOM!I21*HELPER!$G$3))," ") | L21: {=IFERROR(_xlfn.LET(_xlpm.pairs,_xlfn._xlws.FILTER($A$2:$D$391,($A$2:$A$391<>"")*(TRIM($D$2:$D$391)<>"")),_xlpm.uniquePairs,_xlfn.UNIQUE(_xlfn.HSTACK(INDEX(_xlpm.pairs,,1),INDEX(_xlpm.pairs,,4))),_xlpm.sortedPairs,_xlfn._xlws.SORT(_xlpm.uniquePairs,1,1),IF(ROW()-1<=ROWS(_xlpm.sortedPairs),INDEX(_xlpm.sortedPairs,ROW()-1,1),"")),"")} | M21: {=IFERROR(_xlfn.LET(_xlpm.pairs,_xlfn._xlws.FILTER($A$2:$D$391,($A$2:$A$391<>"")*(TRIM($D$2:$D$391)<>"")),_xlpm.uniquePairs,_xlfn.UNIQUE(_xlfn.HSTACK(INDEX(_xlpm.pairs,,1),INDEX(_xlpm.pairs,,4))),_xlpm.sortedPairs,_xlfn._xlws.SORT(_xlpm.uniquePairs,1,1),IF(ROW()-1<=ROWS(_xlpm.sortedPairs),INDEX(_xlpm.sortedPairs,ROW()-1,2),"")),"")} | N21: {=IF(OR(L21="",M21=""),"",IFERROR(INDEX($E$2:$E$391,MATCH(1,($A$2:$A$391=L21)*($D$2:$D$391=M21),0)),""))} | O21: =IF(OR(L21="",M21=""),"",SUMIFS($J$2:$J$391,$A$2:$A$391,L21,$D$2:$D$391,M21)) | Q21: {=IFERROR(INDEX($L$2:$L$391,MATCH(0,COUNTIF($Q$1:Q20,$L$2:$L$391)+IF($L$2:$L$391="",1,0),0)),"")} | R21: =IF(Q21="","",SUMIF($L$2:$L$391,Q21,$O$2:$O$391)) | S21: =IFERROR(Table3[[#This Row],[Price (€/kg)]]*HELPER!$AK$2," ")
A22: TIPA 302FG | B22: Ext. C (In) | C22: PBSA | D22: =IF(C22="","",IFERROR(_xlfn.XLOOKUP(C22,HELPER!$A$2:$A$76,HELPER!$B$2:$B$76,""),D22)) | E22: =IFERROR(_xlfn.XLOOKUP(D22,HELPER!$B:$B,HELPER!$C:$C,""),"") | F22: =IFERROR(_xlfn.XLOOKUP(D22,HELPER!$B:$B,HELPER!$D:$D,""),"") | G22: 8 | H22: 0.818 | I22: =IF(AND(H22<>"",IFERROR(_xlfn.XLOOKUP(D22,HELPER!$B:$B,HELPER!$E:$E,""),"")=""),"Missing price",IFERROR(_xlfn.XLOOKUP(D22,HELPER!$B:$B,HELPER!$E:$E,"")," ")) | J22: =IFERROR(H22*(IF(G22=8,I22*HELPER!$G$2,BOM!I22*HELPER!$G$3))," ") | L22: {=IFERROR(_xlfn.LET(_xlpm.pairs,_xlfn._xlws.FILTER($A$2:$D$391,($A$2:$A$391<>"")*(TRIM($D$2:$D$391)<>"")),_xlpm.uniquePairs,_xlfn.UNIQUE(_xlfn.HSTACK(INDEX(_xlpm.pairs,,1),INDEX(_xlpm.pairs,,4))),_xlpm.sortedPairs,_xlfn._xlws.SORT(_xlpm.uniquePairs,1,1),IF(ROW()-1<=ROWS(_xlpm.sortedPairs),INDEX(_xlpm.sortedPairs,ROW()-1,1),"")),"")} | M22: {=IFERROR(_xlfn.LET(_xlpm.pairs,_xlfn._xlws.FILTER($A$2:$D$391,($A$2:$A$391<>"")*(TRIM($D$2:$D$391)<>"")),_xlpm.uniquePairs,_xlfn.UNIQUE(_xlfn.HSTACK(INDEX(_xlpm.pairs,,1),INDEX(_xlpm.pairs,,4))),_xlpm.sortedPairs,_xlfn._xlws.SORT(_xlpm.uniquePairs,1,1),IF(ROW()-1<=ROWS(_xlpm.sortedPairs),INDEX(_xlpm.sortedPairs,ROW()-1,2),"")),"")} | N22: {=IF(OR(L22="",M22=""),"",IFERROR(INDEX($E$2:$E$391,MATCH(1,($A$2:$A$391=L22)*($D$2:$D$391=M22),0)),""))} | O22: =IF(OR(L22="",M22=""),"",SUMIFS($J$2:$J$391,$A$2:$A$391,L22,$D$2:$D$391,M22)) | Q22: {=IFERROR(INDEX($L$2:$L$391,MATCH(0,COUNTIF($Q$1:Q21,$L$2:$L$391)+IF($L$2:$L$391="",1,0),0)),"")} | R22: =IF(Q22="","",SUMIF($L$2:$L$391,Q22,$O$2:$O$391)) | S22: =IFERROR(Table3[[#This Row],[Price (€/kg)]]*HELPER!$AK$2," ")
A23: TIPA 302FG | B23: Ext. C (In) | C23: PLA | D23: =IF(C23="","",IFERROR(_xlfn.XLOOKUP(C23,HELPER!$A$2:$A$76,HELPER!$B$2:$B$76,""),D23)) | E23: =IFERROR(_xlfn.XLOOKUP(D23,HELPER!$B:$B,HELPER!$C:$C,""),"") | F23: =IFERROR(_xlfn.XLOOKUP(D23,HELPER!$B:$B,HELPER!$D:$D,""),"") | G23: 8 | H23: 0.144 | I23: =IF(AND(H23<>"",IFERROR(_xlfn.XLOOKUP(D23,HELPER!$B:$B,HELPER!$E:$E,""),"")=""),"Missing price",IFERROR(_xlfn.XLOOKUP(D23,HELPER!$B:$B,HELPER!$E:$E,"")," ")) | J23: =IFERROR(H23*(IF(G23=8,I23*HELPER!$G$2,BOM!I23*HELPER!$G$3))," ") | L23: {=IFERROR(_xlfn.LET(_xlpm.pairs,_xlfn._xlws.FILTER($A$2:$D$391,($A$2:$A$391<>"")*(TRIM($D$2:$D$391)<>"")),_xlpm.uniquePairs,_xlfn.UNIQUE(_xlfn.HSTACK(INDEX(_xlpm.pairs,,1),INDEX(_xlpm.pairs,,4))),_xlpm.sortedPairs,_xlfn._xlws.SORT(_xlpm.uniquePairs,1,1),IF(ROW()-1<=ROWS(_xlpm.sortedPairs),INDEX(_xlpm.sortedPairs,ROW()-1,1),"")),"")} | M23: {=IFERROR(_xlfn.LET(_xlpm.pairs,_xlfn._xlws.FILTER($A$2:$D$391,($A$2:$A$391<>"")*(TRIM($D$2:$D$391)<>"")),_xlpm.uniquePairs,_xlfn.UNIQUE(_xlfn.HSTACK(INDEX(_xlpm.pairs,,1),INDEX(_xlpm.pairs,,4))),_xlpm.sortedPairs,_xlfn._xlws.SORT(_xlpm.uniquePairs,1,1),IF(ROW()-1<=ROWS(_xlpm.sortedPairs),INDEX(_xlpm.sortedPairs,ROW()-1,2),"")),"")} | N23: {=IF(OR(L23="",M23=""),"",IFERROR(INDEX($E$2:$E$391,MATCH(1,($A$2:$A$391=L23)*($D$2:$D$391=M23),0)),""))} | O23: =IF(OR(L23="",M23=""),"",SUMIFS($J$2:$J$391,$A$2:$A$391,L23,$D$2:$D$391,M23)) | Q23: {=IFERROR(INDEX($L$2:$L$391,MATCH(0,COUNTIF($Q$1:Q22,$L$2:$L$391)+IF($L$2:$L$391="",1,0),0)),"")} | R23: =IF(Q23="","",SUMIF($L$2:$L$391,Q23,$O$2:$O$391)) | S23: =IFERROR(Table3[[#This Row],[Price (€/kg)]]*HELPER!$AK$2," ")
A24: TIPA 302FG | B24: Ext. C (In) | C24: AB-PLA | D24: =IF(C24="","",IFERROR(_xlfn.XLOOKUP(C24,HELPER!$A$2:$A$76,HELPER!$B$2:$B$76,""),D24)) | E24: =IFERROR(_xlfn.XLOOKUP(D24,HELPER!$B:$B,HELPER!$C:$C,""),"") | F24: =IFERROR(_xlfn.XLOOKUP(D24,HELPER!$B:$B,HELPER!$D:$D,""),"") | G24: 8 | H24: 0.015 | I24: =IF(AND(H24<>"",IFERROR(_xlfn.XLOOKUP(D24,HELPER!$B:$B,HELPER!$E:$E,""),"")=""),"Missing price",IFERROR(_xlfn.XLOOKUP(D24,HELPER!$B:$B,HELPER!$E:$E,"")," ")) | J24: =IFERROR(H24*(IF(G24=8,I24*HELPER!$G$2,BOM!I24*HELPER!$G$3))," ") | L24: {=IFERROR(_xlfn.LET(_xlpm.pairs,_xlfn._xlws.FILTER($A$2:$D$391,($A$2:$A$391<>"")*(TRIM($D$2:$D$391)<>"")),_xlpm.uniquePairs,_xlfn.UNIQUE(_xlfn.HSTACK(INDEX(_xlpm.pairs,,1),INDEX(_xlpm.pairs,,4))),_xlpm.sortedPairs,_xlfn._xlws.SORT(_xlpm.uniquePairs,1,1),IF(ROW()-1<=ROWS(_xlpm.sortedPairs),INDEX(_xlpm.sortedPairs,ROW()-1,1),"")),"")} | M24: {=IFERROR(_xlfn.LET(_xlpm.pairs,_xlfn._xlws.FILTER($A$2:$D$391,($A$2:$A$391<>"")*(TRIM($D$2:$D$391)<>"")),_xlpm.uniquePairs,_xlfn.UNIQUE(_xlfn.HSTACK(INDEX(_xlpm.pairs,,1),INDEX(_xlpm.pairs,,4))),_xlpm.sortedPairs,_xlfn._xlws.SORT(_xlpm.uniquePairs,1,1),IF(ROW()-1<=ROWS(_xlpm.sortedPairs),INDEX(_xlpm.sortedPairs,ROW()-1,2),"")),"")} | N24: {=IF(OR(L24="",M24=""),"",IFERROR(INDEX($E$2:$E$391,MATCH(1,($A$2:$A$391=L24)*($D$2:$D$391=M24),0)),""))} | O24: =IF(OR(L24="",M24=""),"",SUMIFS($J$2:$J$391,$A$2:$A$391,L24,$D$2:$D$391,M24)) | Q24: {=IFERROR(INDEX($L$2:$L$391,MATCH(0,COUNTIF($Q$1:Q23,$L$2:$L$391)+IF($L$2:$L$391="",1,0),0)),"")} | R24: =IF(Q24="","",SUMIF($L$2:$L$391,Q24,$O$2:$O$391)) | S24: =IFERROR(Table3[[#This Row],[Price (€/kg)]]*HELPER!$AK$2," ")
A25: TIPA 302FG | B25: Ext. C (In) | C25: AO-PBS | D25: =IF(C25="","",IFERROR(_xlfn.XLOOKUP(C25,HELPER!$A$2:$A$76,HELPER!$B$2:$B$76,""),D25)) | E25: =IFERROR(_xlfn.XLOOKUP(D25,HELPER!$B:$B,HELPER!$C:$C,""),"") | F25: =IFERROR(_xlfn.XLOOKUP(D25,HELPER!$B:$B,HELPER!$D:$D,""),"") | G25: 8 | H25: 0.015 | I25: =IF(AND(H25<>"",IFERROR(_xlfn.XLOOKUP(D25,HELPER!$B:$B,HELPER!$E:$E,""),"")=""),"Missing price",IFERROR(_xlfn.XLOOKUP(D25,HELPER!$B:$B,HELPER!$E:$E,"")," ")) | J25: =IFERROR(H25*(IF(G25=8,I25*HELPER!$G$2,BOM!I25*HELPER!$G$3))," ") | L25: {=IFERROR(_xlfn.LET(_xlpm.pairs,_xlfn._xlws.FILTER($A$2:$D$391,($A$2:$A$391<>"")*(TRIM($D$2:$D$391)<>"")),_xlpm.uniquePairs,_xlfn.UNIQUE(_xlfn.HSTACK(INDEX(_xlpm.pairs,,1),INDEX(_xlpm.pairs,,4))),_xlpm.sortedPairs,_xlfn._xlws.SORT(_xlpm.uniquePairs,1,1),IF(ROW()-1<=ROWS(_xlpm.sortedPairs),INDEX(_xlpm.sortedPairs,ROW()-1,1),"")),"")} | M25: {=IFERROR(_xlfn.LET(_xlpm.pairs,_xlfn._xlws.FILTER($A$2:$D$391,($A$2:$A$391<>"")*(TRIM($D$2:$D$391)<>"")),_xlpm.uniquePairs,_xlfn.UNIQUE(_xlfn.HSTACK(INDEX(_xlpm.pairs,,1),INDEX(_xlpm.pairs,,4))),_xlpm.sortedPairs,_xlfn._xlws.SORT(_xlpm.uniquePairs,1,1),IF(ROW()-1<=ROWS(_xlpm.sortedPairs),INDEX(_xlpm.sortedPairs,ROW()-1,2),"")),"")} | N25: {=IF(OR(L25="",M25=""),"",IFERROR(INDEX($E$2:$E$391,MATCH(1,($A$2:$A$391=L25)*($D$2:$D$391=M25),0)),""))} | O25: =IF(OR(L25="",M25=""),"",SUMIFS($J$2:$J$391,$A$2:$A$391,L25,$D$2:$D$391,M25)) | Q25: {=IFERROR(INDEX($L$2:$L$391,MATCH(0,COUNTIF($Q$1:Q24,$L$2:$L$391)+IF($L$2:$L$391="",1,0),0)),"")} | R25: =IF(Q25="","",SUMIF($L$2:$L$391,Q25,$O$2:$O$391)) | S25: =IFERROR(Table3[[#This Row],[Price (€/kg)]]*HELPER!$AK$2," ")
A26: TIPA 302FG | B26: Ext. C (In) | C26: SLAB-PBSA | D26: =IF(C26="","",IFERROR(_xlfn.XLOOKUP(C26,HELPER!$A$2:$A$76,HELPER!$B$2:$B$76,""),D26)) | E26: =IFERROR(_xlfn.XLOOKUP(D26,HELPER!$B:$B,HELPER!$C:$C,""),"") | F26: =IFERROR(_xlfn.XLOOKUP(D26,HELPER!$B:$B,HELPER!$D:$D,""),"") | G26: 8 | H26: 0.008 | I26: =IF(AND(H26<>"",IFERROR(_xlfn.XLOOKUP(D26,HELPER!$B:$B,HELPER!$E:$E,""),"")=""),"Missing price",IFERROR(_xlfn.XLOOKUP(D26,HELPER!$B:$B,HELPER!$E:$E,"")," ")) | J26: =IFERROR(H26*(IF(G26=8,I26*HELPER!$G$2,BOM!I26*HELPER!$G$3))," ") | L26: {=IFERROR(_xlfn.LET(_xlpm.pairs,_xlfn._xlws.FILTER($A$2:$D$391,($A$2:$A$391<>"")*(TRIM($D$2:$D$391)<>"")),_xlpm.uniquePairs,_xlfn.UNIQUE(_xlfn.HSTACK(INDEX(_xlpm.pairs,,1),INDEX(_xlpm.pairs,,4))),_xlpm.sortedPairs,_xlfn._xlws.SORT(_xlpm.uniquePairs,1,1),IF(ROW()-1<=ROWS(_xlpm.sortedPairs),INDEX(_xlpm.sortedPairs,ROW()-1,1),"")),"")} | M26: {=IFERROR(_xlfn.LET(_xlpm.pairs,_xlfn._xlws.FILTER($A$2:$D$391,($A$2:$A$391<>"")*(TRIM($D$2:$D$391)<>"")),_xlpm.uniquePairs,_xlfn.UNIQUE(_xlfn.HSTACK(INDEX(_xlpm.pairs,,1),INDEX(_xlpm.pairs,,4))),_xlpm.sortedPairs,_xlfn._xlws.SORT(_xlpm.uniquePairs,1,1),IF(ROW()-1<=ROWS(_xlpm.sortedPairs),INDEX(_xlpm.sortedPairs,ROW()-1,2),"")),"")} | N26: {=IF(OR(L26="",M26=""),"",IFERROR(INDEX($E$2:$E$391,MATCH(1,($A$2:$A$391=L26)*($D$2:$D$391=M26),0)),""))} | O26: =IF(OR(L26="",M26=""),"",SUMIFS($J$2:$J$391,$A$2:$A$391,L26,$D$2:$D$391,M26)) | Q26: {=IFERROR(INDEX($L$2:$L$391,MATCH(0,COUNTIF($Q$1:Q25,$L$2:$L$391)+IF($L$2:$L$391="",1,0),0)),"")} | R26: =IF(Q26="","",SUMIF($L$2:$L$391,Q26,$O$2:$O$391)) | S26: =IFERROR(Table3[[#This Row],[Price (€/kg)]]*HELPER!$AK$2," ")
A27: TIPA 302FG | B27: Ext. C (In) | D27: =IF(C27="","",IFERROR(_xlfn.XLOOKUP(C27,HELPER!$A$2:$A$76,HELPER!$B$2:$B$76,""),D27)) | E27: =IFERROR(_xlfn.XLOOKUP(D27,HELPER!$B:$B,HELPER!$C:$C,""),"") | F27: =IFERROR(_xlfn.XLOOKUP(D27,HELPER!$B:$B,HELPER!$D:$D,""),"") | G27: 8 | I27: =IF(AND(H27<>"",IFERROR(_xlfn.XLOOKUP(D27,HELPER!$B:$B,HELPER!$E:$E,""),"")=""),"Missing price",IFERROR(_xlfn.XLOOKUP(D27,HELPER!$B:$B,HELPER!$E:$E,"")," ")) | J27: =IFERROR(H27*(IF(G27=8,I27*HELPER!$G$2,BOM!I27*HELPER!$G$3))," ") | L27: {=IFERROR(_xlfn.LET(_xlpm.pairs,_xlfn._xlws.FILTER($A$2:$D$391,($A$2:$A$391<>"")*(TRIM($D$2:$D$391)<>"")),_xlpm.uniquePairs,_xlfn.UNIQUE(_xlfn.HSTACK(INDEX(_xlpm.pairs,,1),INDEX(_xlpm.pairs,,4))),_xlpm.sortedPairs,_xlfn._xlws.SORT(_xlpm.uniquePairs,1,1),IF(ROW()-1<=ROWS(_xlpm.sortedPairs),INDEX(_xlpm.sortedPairs,ROW()-1,1),"")),"")} | M27: {=IFERROR(_xlfn.LET(_xlpm.pairs,_xlfn._xlws.FILTER($A$2:$D$391,($A$2:$A$391<>"")*(TRIM($D$2:$D$391)<>"")),_xlpm.uniquePairs,_xlfn.UNIQUE(_xlfn.HSTACK(INDEX(_xlpm.pairs,,1),INDEX(_xlpm.pairs,,4))),_xlpm.sortedPairs,_xlfn._xlws.SORT(_xlpm.uniquePairs,1,1),IF(ROW()-1<=ROWS(_xlpm.sortedPairs),INDEX(_xlpm.sortedPairs,ROW()-1,2),"")),"")} | N27: {=IF(OR(L27="",M27=""),"",IFERROR(INDEX($E$2:$E$391,MATCH(1,($A$2:$A$391=L27)*($D$2:$D$391=M27),0)),""))} | O27: =IF(OR(L27="",M27=""),"",SUMIFS($J$2:$J$391,$A$2:$A$391,L27,$D$2:$D$391,M27)) | Q27: {=IFERROR(INDEX($L$2:$L$391,MATCH(0,COUNTIF($Q$1:Q26,$L$2:$L$391)+IF($L$2:$L$391="",1,0),0)),"")} | R27: =IF(Q27="","",SUMIF($L$2:$L$391,Q27,$O$2:$O$391)) | S27: =IFERROR(Table3[[#This Row],[Price (€/kg)]]*HELPER!$AK$2," ")
A28: TIPA 302FG | B28: Ext. C (In) | D28: =IF(C28="","",IFERROR(_xlfn.XLOOKUP(C28,HELPER!$A$2:$A$76,HELPER!$B$2:$B$76,""),D28)) | E28: =IFERROR(_xlfn.XLOOKUP(D28,HELPER!$B:$B,HELPER!$C:$C,""),"") | F28: =IFERROR(_xlfn.XLOOKUP(D28,HELPER!$B:$B,HELPER!$D:$D,""),"") | G28: 8 | I28: =IF(AND(H28<>"",IFERROR(_xlfn.XLOOKUP(D28,HELPER!$B:$B,HELPER!$E:$E,""),"")=""),"Missing price",IFERROR(_xlfn.XLOOKUP(D28,HELPER!$B:$B,HELPER!$E:$E,"")," ")) | J28: =IFERROR(H28*(IF(G28=8,I28*HELPER!$G$2,BOM!I28*HELPER!$G$3))," ") | L28: {=IFERROR(_xlfn.LET(_xlpm.pairs,_xlfn._xlws.FILTER($A$2:$D$391,($A$2:$A$391<>"")*(TRIM($D$2:$D$391)<>"")),_xlpm.uniquePairs,_xlfn.UNIQUE(_xlfn.HSTACK(INDEX(_xlpm.pairs,,1),INDEX(_xlpm.pairs,,4))),_xlpm.sortedPairs,_xlfn._xlws.SORT(_xlpm.uniquePairs,1,1),IF(ROW()-1<=ROWS(_xlpm.sortedPairs),INDEX(_xlpm.sortedPairs,ROW()-1,1),"")),"")} | M28: {=IFERROR(_xlfn.LET(_xlpm.pairs,_xlfn._xlws.FILTER($A$2:$D$391,($A$2:$A$391<>"")*(TRIM($D$2:$D$391)<>"")),_xlpm.uniquePairs,_xlfn.UNIQUE(_xlfn.HSTACK(INDEX(_xlpm.pairs,,1),INDEX(_xlpm.pairs,,4))),_xlpm.sortedPairs,_xlfn._xlws.SORT(_xlpm.uniquePairs,1,1),IF(ROW()-1<=ROWS(_xlpm.sortedPairs),INDEX(_xlpm.sortedPairs,ROW()-1,2),"")),"")} | N28: {=IF(OR(L28="",M28=""),"",IFERROR(INDEX($E$2:$E$391,MATCH(1,($A$2:$A$391=L28)*($D$2:$D$391=M28),0)),""))} | O28: =IF(OR(L28="",M28=""),"",SUMIFS($J$2:$J$391,$A$2:$A$391,L28,$D$2:$D$391,M28)) | Q28: {=IFERROR(INDEX($L$2:$L$391,MATCH(0,COUNTIF($Q$1:Q27,$L$2:$L$391)+IF($L$2:$L$391="",1,0),0)),"")} | R28: =IF(Q28="","",SUMIF($L$2:$L$391,Q28,$O$2:$O$391)) | S28: =IFERROR(Table3[[#This Row],[Price (€/kg)]]*HELPER!$AK$2," ")
